dash-app-1  | Dash is running on http://0.0.0.0:8050/
dash-app-1  | 
dash-app-1  |  * Serving Flask app 'app'
dash-app-1  |  * Debug mode: off
dash-app-1  | WARNING: This is a development server. Do not use it in a production deployment. Use a production WSGI server instead.
dash-app-1  |  * Running on all addresses (0.0.0.0)
dash-app-1  |  * Running on http://127.0.0.1:8050
dash-app-1  |  * Running on http://172.18.0.3:8050
dash-app-1  | Press CTRL+C to quit
dash-app-1  | 172.18.0.1 - - [30/Sep/2025 18:17:15] "GET / HTTP/1.1" 200 -
dash-app-1  | 172.18.0.1 - - [30/Sep/2025 18:17:16] "GET /_dash-component-suites/dash/deps/react@18.v3_0_4m1759168589.3.1.min.js HTTP/1.1" 200 -
dash-app-1  | 172.18.0.1 - - [30/Sep/2025 18:17:16] "GET /_dash-component-suites/dash/deps/polyfill@7.v3_0_4m1759168589.12.1.min.js HTTP/1.1" 200 -
dash-app-1  | 172.18.0.1 - - [30/Sep/2025 18:17:16] "GET /_dash-component-suites/dash/deps/react-dom@18.v3_0_4m1759168589.3.1.min.js HTTP/1.1" 200 -
dash-app-1  | 172.18.0.1 - - [30/Sep/2025 18:17:16] "GET /_dash-component-suites/dash/dash-renderer/build/dash_renderer.v3_0_4m1759168588.min.js HTTP/1.1" 200 -
dash-app-1  | 172.18.0.1 - - [30/Sep/2025 18:17:16] "GET /_dash-component-suites/dash_bootstrap_components/_components/dash_bootstrap_components.v2_0_3m1759168589.min.js HTTP/1.1" 200 -
dash-app-1  | 172.18.0.1 - - [30/Sep/2025 18:17:16] "GET /_dash-component-suites/dash/deps/prop-types@15.v3_0_4m1759168589.8.1.min.js HTTP/1.1" 200 -
dash-app-1  | 172.18.0.1 - - [30/Sep/2025 18:17:18] "GET /_dash-component-suites/dash/dcc/dash_core_components.v3_0_6m1759168589.js HTTP/1.1" 200 -
dash-app-1  | 172.18.0.1 - - [30/Sep/2025 18:17:18] "GET /_dash-component-suites/dash/dcc/dash_core_components-shared.v3_0_6m1759168589.js HTTP/1.1" 200 -
dash-app-1  | 172.18.0.1 - - [30/Sep/2025 18:17:18] "GET /_dash-component-suites/dash/html/dash_html_components.v3_0_2m1759168589.min.js HTTP/1.1" 200 -
dash-app-1  | 172.18.0.1 - - [30/Sep/2025 18:17:19] "GET /_dash-component-suites/dash/dash_table/bundle.v6_0_2m1759168589.js HTTP/1.1" 200 -
dash-app-1  | 172.18.0.1 - - [30/Sep/2025 18:17:21] "GET /_dash-dependencies HTTP/1.1" 200 -
dash-app-1  | 172.18.0.1 - - [30/Sep/2025 18:17:21] "GET /_dash-layout HTTP/1.1" 200 -
dash-app-1  | 172.18.0.1 - - [30/Sep/2025 18:17:23] "POST /_dash-update-component HTTP/1.1" 200 -
dash-app-1  | 172.18.0.1 - - [30/Sep/2025 18:17:23] "GET /assets/logo.png HTTP/1.1" 200 -
dash-app-1  | 172.18.0.1 - - [30/Sep/2025 18:17:23] "GET /assets/wikimedia-logo.png HTTP/1.1" 200 -
dash-app-1  | 172.18.0.1 - - [30/Sep/2025 18:17:27] "GET /main HTTP/1.1" 200 -
dash-app-1  | 172.18.0.1 - - [30/Sep/2025 18:17:28] "GET /_dash-layout HTTP/1.1" 200 -
dash-app-1  | 172.18.0.1 - - [30/Sep/2025 18:17:28] "GET /_dash-dependencies HTTP/1.1" 200 -
dash-app-1  | 172.18.0.1 - - [30/Sep/2025 18:17:29] "POST /_dash-update-component HTTP/1.1" 200 -
dash-app-1  | 172.18.0.1 - - [30/Sep/2025 18:17:29] "GET /assets/wikimedia-logo.png HTTP/1.1" 304 -
dash-app-1  | 172.18.0.1 - - [30/Sep/2025 18:17:29] "GET /assets/logo.png HTTP/1.1" 304 -
dash-app-1  | 172.18.0.1 - - [30/Sep/2025 18:17:30] "POST /_dash-update-component HTTP/1.1" 200 -
dash-app-1  | 172.18.0.1 - - [30/Sep/2025 18:17:31] "POST /_dash-update-component HTTP/1.1" 200 -
dash-app-1  | 172.18.0.1 - - [30/Sep/2025 18:17:31] "GET /_dash-component-suites/dash/dcc/async-dropdown.js HTTP/1.1" 304 -
dash-app-1  | 172.18.0.1 - - [30/Sep/2025 18:17:31] "GET /_dash-component-suites/dash/dcc/async-markdown.js HTTP/1.1" 304 -
dash-app-1  | [2025-09-30 18:17:31,798] ERROR in app: Exception on /_dash-update-component [POST]
dash-app-1  | Traceback (most recent call last):
dash-app-1  |   File "/usr/local/lib/python3.12/site-packages/sqlalchemy/engine/base.py", line 146, in __init__
dash-app-1  |     self._dbapi_connection = engine.raw_connection()
dash-app-1  |                              ^^^^^^^^^^^^^^^^^^^^^^^
dash-app-1  |   File "/usr/local/lib/python3.12/site-packages/sqlalchemy/engine/base.py", line 3302, in raw_connection
dash-app-1  |     return self.pool.connect()
dash-app-1  |            ^^^^^^^^^^^^^^^^^^^
dash-app-1  |   File "/usr/local/lib/python3.12/site-packages/sqlalchemy/pool/base.py", line 449, in connect
dash-app-1  |     return _ConnectionFairy._checkout(self)
dash-app-1  |            ^^^^^^^^^^^^^^^^^^^^^^^^^^^^^^^^
dash-app-1  |   File "/usr/local/lib/python3.12/site-packages/sqlalchemy/pool/base.py", line 1263, in _checkout
dash-app-1  |     fairy = _ConnectionRecord.checkout(pool)
dash-app-1  |             ^^^^^^^^^^^^^^^^^^^^^^^^^^^^^^^^
dash-app-1  |   File "/usr/local/lib/python3.12/site-packages/sqlalchemy/pool/base.py", line 712, in checkout
dash-app-1  |     rec = pool._do_get()
dash-app-1  |           ^^^^^^^^^^^^^^
dash-app-1  |   File "/usr/local/lib/python3.12/site-packages/sqlalchemy/pool/impl.py", line 179, in _do_get
dash-app-1  |     with util.safe_reraise():
dash-app-1  |          ^^^^^^^^^^^^^^^^^^^
dash-app-1  |   File "/usr/local/lib/python3.12/site-packages/sqlalchemy/util/langhelpers.py", line 146, in __exit__
dash-app-1  |     raise exc_value.with_traceback(exc_tb)
dash-app-1  |   File "/usr/local/lib/python3.12/site-packages/sqlalchemy/pool/impl.py", line 177, in _do_get
dash-app-1  |     return self._create_connection()
dash-app-1  |            ^^^^^^^^^^^^^^^^^^^^^^^^^
dash-app-1  |   File "/usr/local/lib/python3.12/site-packages/sqlalchemy/pool/base.py", line 390, in _create_connection
dash-app-1  |     return _ConnectionRecord(self)
dash-app-1  |            ^^^^^^^^^^^^^^^^^^^^^^^
dash-app-1  |   File "/usr/local/lib/python3.12/site-packages/sqlalchemy/pool/base.py", line 674, in __init__
dash-app-1  |     self.__connect()
dash-app-1  |   File "/usr/local/lib/python3.12/site-packages/sqlalchemy/pool/base.py", line 900, in __connect
dash-app-1  |     with util.safe_reraise():
dash-app-1  |          ^^^^^^^^^^^^^^^^^^^
dash-app-1  |   File "/usr/local/lib/python3.12/site-packages/sqlalchemy/util/langhelpers.py", line 146, in __exit__
dash-app-1  |     raise exc_value.with_traceback(exc_tb)
dash-app-1  |   File "/usr/local/lib/python3.12/site-packages/sqlalchemy/pool/base.py", line 896, in __connect
dash-app-1  |     self.dbapi_connection = connection = pool._invoke_creator(self)
dash-app-1  |                                          ^^^^^^^^^^^^^^^^^^^^^^^^^^
dash-app-1  |   File "/usr/local/lib/python3.12/site-packages/sqlalchemy/engine/create.py", line 643, in connect
dash-app-1  |     return dialect.connect(*cargs, **cparams)
dash-app-1  |            ^^^^^^^^^^^^^^^^^^^^^^^^^^^^^^^^^^
dash-app-1  |   File "/usr/local/lib/python3.12/site-packages/sqlalchemy/engine/default.py", line 621, in connect
dash-app-1  |     return self.loaded_dbapi.connect(*cargs, **cparams)
dash-app-1  |            ^^^^^^^^^^^^^^^^^^^^^^^^^^^^^^^^^^^^^^^^^^^^
dash-app-1  |   File "/usr/local/lib/python3.12/site-packages/psycopg2/__init__.py", line 122, in connect
dash-app-1  |     conn = _connect(dsn, connection_factory=connection_factory, **kwasync)
dash-app-1  |            ^^^^^^^^^^^^^^^^^^^^^^^^^^^^^^^^^^^^^^^^^^^^^^^^^^^^^^^^^^^^^^^
dash-app-1  | psycopg2.OperationalError: connection to server at "postgres" (172.18.0.6), port 5432 failed: FATAL:  password authentication failed for user "None"
dash-app-1  | 
dash-app-1  | 
dash-app-1  | The above exception was the direct cause of the following exception:
dash-app-1  | 
dash-app-1  | Traceback (most recent call last):
dash-app-1  |   File "/usr/local/lib/python3.12/site-packages/flask/app.py", line 1473, in wsgi_app
dash-app-1  |     response = self.full_dispatch_request()
dash-app-1  |                ^^^^^^^^^^^^^^^^^^^^^^^^^^^^
dash-app-1  |   File "/usr/local/lib/python3.12/site-packages/flask/app.py", line 882, in full_dispatch_request
dash-app-1  |     rv = self.handle_user_exception(e)
dash-app-1  |          ^^^^^^^^^^^^^^^^^^^^^^^^^^^^^
dash-app-1  |   File "/usr/local/lib/python3.12/site-packages/flask/app.py", line 880, in full_dispatch_request
dash-app-1  |     rv = self.dispatch_request()
dash-app-1  |          ^^^^^^^^^^^^^^^^^^^^^^^
dash-app-1  |   File "/usr/local/lib/python3.12/site-packages/flask/app.py", line 865, in dispatch_request
dash-app-1  |     return self.ensure_sync(self.view_functions[rule.endpoint])(**view_args)  # type: ignore[no-any-return]
dash-app-1  |            ^^^^^^^^^^^^^^^^^^^^^^^^^^^^^^^^^^^^^^^^^^^^^^^^^^^^^^^^^^^^^^^^^
dash-app-1  |   File "/usr/local/lib/python3.12/site-packages/dash/dash.py", line 1414, in dispatch
dash-app-1  |     ctx.run(
dash-app-1  |   File "/usr/local/lib/python3.12/site-packages/dash/_callback.py", line 536, in add_context
dash-app-1  |     raise err
dash-app-1  |   File "/usr/local/lib/python3.12/site-packages/dash/_callback.py", line 525, in add_context
dash-app-1  |     output_value = _invoke_callback(func, *func_args, **func_kwargs)  # type: ignore[reportArgumentType]
dash-app-1  |                    ^^^^^^^^^^^^^^^^^^^^^^^^^^^^^^^^^^^^^^^^^^^^^^^^^
dash-app-1  |   File "/usr/local/lib/python3.12/site-packages/dash/_callback.py", line 47, in _invoke_callback
dash-app-1  |     return func(*args, **kwargs)  # %% callback invoked %%
dash-app-1  |            ^^^^^^^^^^^^^^^^^^^^^
dash-app-1  |   File "/app/apps/main_app.py", line 1587, in change_graph
dash-app-1  |     fig = activity_graph(language, user_type, time_type)
dash-app-1  |           ^^^^^^^^^^^^^^^^^^^^^^^^^^^^^^^^^^^^^^^^^^^^^^
dash-app-1  |   File "/app/apps/main_app.py", line 581, in activity_graph
dash-app-1  |     df = pd.read_sql_query(stmt, engine, params=params)
dash-app-1  |          ^^^^^^^^^^^^^^^^^^^^^^^^^^^^^^^^^^^^^^^^^^^^^^
dash-app-1  |   File "/usr/local/lib/python3.12/site-packages/pandas/io/sql.py", line 525, in read_sql_query
dash-app-1  |     with pandasSQL_builder(con) as pandas_sql:
dash-app-1  |          ^^^^^^^^^^^^^^^^^^^^^^
dash-app-1  |   File "/usr/local/lib/python3.12/site-packages/pandas/io/sql.py", line 906, in pandasSQL_builder
dash-app-1  |     return SQLDatabase(con, schema, need_transaction)
dash-app-1  |            ^^^^^^^^^^^^^^^^^^^^^^^^^^^^^^^^^^^^^^^^^^
dash-app-1  |   File "/usr/local/lib/python3.12/site-packages/pandas/io/sql.py", line 1636, in __init__
dash-app-1  |     con = self.exit_stack.enter_context(con.connect())
dash-app-1  |                                         ^^^^^^^^^^^^^
dash-app-1  |   File "/usr/local/lib/python3.12/site-packages/sqlalchemy/engine/base.py", line 3278, in connect
dash-app-1  |     return self._connection_cls(self)
dash-app-1  |            ^^^^^^^^^^^^^^^^^^^^^^^^^^
dash-app-1  |   File "/usr/local/lib/python3.12/site-packages/sqlalchemy/engine/base.py", line 148, in __init__
dash-app-1  |     Connection._handle_dbapi_exception_noconnection(
dash-app-1  |   File "/usr/local/lib/python3.12/site-packages/sqlalchemy/engine/base.py", line 2442, in _handle_dbapi_exception_noconnection
dash-app-1  |     raise sqlalchemy_exception.with_traceback(exc_info[2]) from e
dash-app-1  |   File "/usr/local/lib/python3.12/site-packages/sqlalchemy/engine/base.py", line 146, in __init__
dash-app-1  |     self._dbapi_connection = engine.raw_connection()
dash-app-1  |                              ^^^^^^^^^^^^^^^^^^^^^^^
dash-app-1  |   File "/usr/local/lib/python3.12/site-packages/sqlalchemy/engine/base.py", line 3302, in raw_connection
dash-app-1  |     return self.pool.connect()
dash-app-1  |            ^^^^^^^^^^^^^^^^^^^
dash-app-1  |   File "/usr/local/lib/python3.12/site-packages/sqlalchemy/pool/base.py", line 449, in connect
dash-app-1  |     return _ConnectionFairy._checkout(self)
dash-app-1  |            ^^^^^^^^^^^^^^^^^^^^^^^^^^^^^^^^
dash-app-1  |   File "/usr/local/lib/python3.12/site-packages/sqlalchemy/pool/base.py", line 1263, in _checkout
dash-app-1  |     fairy = _ConnectionRecord.checkout(pool)
dash-app-1  |             ^^^^^^^^^^^^^^^^^^^^^^^^^^^^^^^^
dash-app-1  |   File "/usr/local/lib/python3.12/site-packages/sqlalchemy/pool/base.py", line 712, in checkout
dash-app-1  |     rec = pool._do_get()
dash-app-1  |           ^^^^^^^^^^^^^^
dash-app-1  |   File "/usr/local/lib/python3.12/site-packages/sqlalchemy/pool/impl.py", line 179, in _do_get
dash-app-1  |     with util.safe_reraise():
dash-app-1  |          ^^^^^^^^^^^^^^^^^^^
dash-app-1  |   File "/usr/local/lib/python3.12/site-packages/sqlalchemy/util/langhelpers.py", line 146, in __exit__
dash-app-1  |     raise exc_value.with_traceback(exc_tb)
dash-app-1  |   File "/usr/local/lib/python3.12/site-packages/sqlalchemy/pool/impl.py", line 177, in _do_get
dash-app-1  |     return self._create_connection()
dash-app-1  |            ^^^^^^^^^^^^^^^^^^^^^^^^^
dash-app-1  |   File "/usr/local/lib/python3.12/site-packages/sqlalchemy/pool/base.py", line 390, in _create_connection
dash-app-1  |     return _ConnectionRecord(self)
dash-app-1  |            ^^^^^^^^^^^^^^^^^^^^^^^
dash-app-1  |   File "/usr/local/lib/python3.12/site-packages/sqlalchemy/pool/base.py", line 674, in __init__
dash-app-1  |     self.__connect()
dash-app-1  |   File "/usr/local/lib/python3.12/site-packages/sqlalchemy/pool/base.py", line 900, in __connect
dash-app-1  |     with util.safe_reraise():
dash-app-1  |          ^^^^^^^^^^^^^^^^^^^
dash-app-1  |   File "/usr/local/lib/python3.12/site-packages/sqlalchemy/util/langhelpers.py", line 146, in __exit__
dash-app-1  |     raise exc_value.with_traceback(exc_tb)
dash-app-1  |   File "/usr/local/lib/python3.12/site-packages/sqlalchemy/pool/base.py", line 896, in __connect
dash-app-1  |     self.dbapi_connection = connection = pool._invoke_creator(self)
dash-app-1  |                                          ^^^^^^^^^^^^^^^^^^^^^^^^^^
dash-app-1  |   File "/usr/local/lib/python3.12/site-packages/sqlalchemy/engine/create.py", line 643, in connect
dash-app-1  |     return dialect.connect(*cargs, **cparams)
dash-app-1  |            ^^^^^^^^^^^^^^^^^^^^^^^^^^^^^^^^^^
dash-app-1  |   File "/usr/local/lib/python3.12/site-packages/sqlalchemy/engine/default.py", line 621, in connect
dash-app-1  |     return self.loaded_dbapi.connect(*cargs, **cparams)
dash-app-1  |            ^^^^^^^^^^^^^^^^^^^^^^^^^^^^^^^^^^^^^^^^^^^^
dash-app-1  |   File "/usr/local/lib/python3.12/site-packages/psycopg2/__init__.py", line 122, in connect
dash-app-1  |     conn = _connect(dsn, connection_factory=connection_factory, **kwasync)
dash-app-1  |            ^^^^^^^^^^^^^^^^^^^^^^^^^^^^^^^^^^^^^^^^^^^^^^^^^^^^^^^^^^^^^^^
dash-app-1  | sqlalchemy.exc.OperationalError: (psycopg2.OperationalError) connection to server at "postgres" (172.18.0.6), port 5432 failed: FATAL:  password authentication failed for user "None"
dash-app-1  | 
dash-app-1  | (Background on this error at: https://sqlalche.me/e/20/e3q8)
dash-app-1  | 172.18.0.1 - - [30/Sep/2025 18:17:31] "POST /_dash-update-component HTTP/1.1" 500 -
dash-app-1  | 172.18.0.1 - - [30/Sep/2025 18:17:32] "POST /_dash-update-component HTTP/1.1" 200 -
dash-app-1  | [2025-09-30 18:17:32,938] ERROR in app: Exception on /_dash-update-component [POST]
dash-app-1  | Traceback (most recent call last):
dash-app-1  |   File "/usr/local/lib/python3.12/site-packages/flask/app.py", line 1473, in wsgi_app
dash-app-1  |     response = self.full_dispatch_request()
dash-app-1  |                ^^^^^^^^^^^^^^^^^^^^^^^^^^^^
dash-app-1  |   File "/usr/local/lib/python3.12/site-packages/flask/app.py", line 882, in full_dispatch_request
dash-app-1  |     rv = self.handle_user_exception(e)
dash-app-1  |          ^^^^^^^^^^^^^^^^^^^^^^^^^^^^^
dash-app-1  |   File "/usr/local/lib/python3.12/site-packages/flask/app.py", line 880, in full_dispatch_request
dash-app-1  |     rv = self.dispatch_request()
dash-app-1  |          ^^^^^^^^^^^^^^^^^^^^^^^
dash-app-1  |   File "/usr/local/lib/python3.12/site-packages/flask/app.py", line 865, in dispatch_request
dash-app-1  |     return self.ensure_sync(self.view_functions[rule.endpoint])(**view_args)  # type: ignore[no-any-return]
dash-app-1  |            ^^^^^^^^^^^^^^^^^^^^^^^^^^^^^^^^^^^^^^^^^^^^^^^^^^^^^^^^^^^^^^^^^
dash-app-1  |   File "/usr/local/lib/python3.12/site-packages/dash/dash.py", line 1414, in dispatch
dash-app-1  |     ctx.run(
dash-app-1  |   File "/usr/local/lib/python3.12/site-packages/dash/_callback.py", line 554, in add_context
dash-app-1  |     flat_output_values = flatten_grouping(output_value, output)
dash-app-1  |                          ^^^^^^^^^^^^^^^^^^^^^^^^^^^^^^^^^^^^^^
dash-app-1  |   File "/usr/local/lib/python3.12/site-packages/dash/_grouping.py", line 35, in flatten_grouping
dash-app-1  |     validate_grouping(grouping, schema)
dash-app-1  |   File "/usr/local/lib/python3.12/site-packages/dash/_grouping.py", line 210, in validate_grouping
dash-app-1  |     SchemaTypeValidationError.check(grouping, full_schema, path, (tuple, list))
dash-app-1  |   File "/usr/local/lib/python3.12/site-packages/dash/_grouping.py", line 162, in check
dash-app-1  |     raise SchemaTypeValidationError(value, full_schema, path, expected_type)
dash-app-1  | dash._grouping.SchemaTypeValidationError: Schema: [<Output `graph_container.children`>, <Output `retention_rate.disabled`>, <Output `admin.disabled`>, <Output `percentage_number.options`>, <Output `year_yearmonth.options`>, <Output `active_veryactive.options`>]
dash-app-1  | Path: ()
dash-app-1  | Expected type: (<class 'tuple'>, <class 'list'>)
dash-app-1  | Received value of type <class 'NoneType'>:
dash-app-1  |     None
dash-app-1  | 172.18.0.1 - - [30/Sep/2025 18:17:32] "POST /_dash-update-component HTTP/1.1" 500 -
dash-app-1  | 172.18.0.1 - - [30/Sep/2025 18:17:32] "GET /_dash-component-suites/dash/dcc/async-highlight.js HTTP/1.1" 304 -
dash-app-1  | 172.18.0.1 - - [30/Sep/2025 18:21:21] "GET /main?metric=None&langcode=piedmontese+(pms)&active_veryactive=5&year_yearmonth=ym&retention_rate=60d&percentage_number=perc&admin=sysop HTTP/1.1" 200 -
dash-app-1  | 172.18.0.1 - - [30/Sep/2025 18:21:21] "GET /_dash-dependencies HTTP/1.1" 200 -
dash-app-1  | 172.18.0.1 - - [30/Sep/2025 18:21:21] "GET /_dash-layout HTTP/1.1" 200 -
dash-app-1  | 172.18.0.1 - - [30/Sep/2025 18:21:21] "GET /_favicon.ico?v=3.0.4 HTTP/1.1" 200 -
dash-app-1  | 172.18.0.1 - - [30/Sep/2025 18:21:23] "POST /_dash-update-component HTTP/1.1" 200 -
dash-app-1  | 172.18.0.1 - - [30/Sep/2025 18:21:23] "GET /assets/logo.png HTTP/1.1" 304 -
dash-app-1  | 172.18.0.1 - - [30/Sep/2025 18:21:23] "GET /assets/wikimedia-logo.png HTTP/1.1" 304 -
dash-app-1  | [2025-09-30 18:21:24,527] ERROR in app: Exception on /_dash-update-component [POST]
dash-app-1  | Traceback (most recent call last):
dash-app-1  |   File "/usr/local/lib/python3.12/site-packages/flask/app.py", line 1473, in wsgi_app
dash-app-1  |     response = self.full_dispatch_request()
dash-app-1  |                ^^^^^^^^^^^^^^^^^^^^^^^^^^^^
dash-app-1  |   File "/usr/local/lib/python3.12/site-packages/flask/app.py", line 882, in full_dispatch_request
dash-app-1  |     rv = self.handle_user_exception(e)
dash-app-1  |          ^^^^^^^^^^^^^^^^^^^^^^^^^^^^^
dash-app-1  |   File "/usr/local/lib/python3.12/site-packages/flask/app.py", line 880, in full_dispatch_request
dash-app-1  |     rv = self.dispatch_request()
dash-app-1  |          ^^^^^^^^^^^^^^^^^^^^^^^
dash-app-1  |   File "/usr/local/lib/python3.12/site-packages/flask/app.py", line 865, in dispatch_request
dash-app-1  |     return self.ensure_sync(self.view_functions[rule.endpoint])(**view_args)  # type: ignore[no-any-return]
dash-app-1  |            ^^^^^^^^^^^^^^^^^^^^^^^^^^^^^^^^^^^^^^^^^^^^^^^^^^^^^^^^^^^^^^^^^
dash-app-1  |   File "/usr/local/lib/python3.12/site-packages/dash/dash.py", line 1414, in dispatch
dash-app-1  |     ctx.run(
dash-app-1  |   File "/usr/local/lib/python3.12/site-packages/dash/_callback.py", line 536, in add_context
dash-app-1  |     raise err
dash-app-1  |   File "/usr/local/lib/python3.12/site-packages/dash/_callback.py", line 525, in add_context
dash-app-1  |     output_value = _invoke_callback(func, *func_args, **func_kwargs)  # type: ignore[reportArgumentType]
dash-app-1  |                    ^^^^^^^^^^^^^^^^^^^^^^^^^^^^^^^^^^^^^^^^^^^^^^^^^
dash-app-1  |   File "/usr/local/lib/python3.12/site-packages/dash/_callback.py", line 47, in _invoke_callback
dash-app-1  |     return func(*args, **kwargs)  # %% callback invoked %%
dash-app-1  |            ^^^^^^^^^^^^^^^^^^^^^
dash-app-1  |   File "/app/apps/main_app.py", line 278, in page_load
dash-app-1  |     return main_app_build_layout(state)
dash-app-1  |            ^^^^^^^^^^^^^^^^^^^^^^^^^^^^
dash-app-1  |   File "/app/apps/main_app.py", line 294, in main_app_build_layout
dash-app-1  |     main_app.title = "Vital Signs"+title_addenda
dash-app-1  |     ^^^^^^^^
dash-app-1  | NameError: name 'main_app' is not defined
dash-app-1  | 172.18.0.1 - - [30/Sep/2025 18:21:24] "POST /_dash-update-component HTTP/1.1" 500 -
dash-app-1  | 172.18.0.1 - - [30/Sep/2025 18:21:58] "GET /main?metric=None&langcode=piedmontese+(pms)&active_veryactive=5&year_yearmonth=ym&retention_rate=60d&percentage_number=perc&admin=sysop HTTP/1.1" 200 -
dash-app-1  | 172.18.0.1 - - [30/Sep/2025 18:22:00] "GET /_dash-layout HTTP/1.1" 200 -
dash-app-1  | 172.18.0.1 - - [30/Sep/2025 18:22:00] "GET /_dash-dependencies HTTP/1.1" 200 -
dash-app-1  | 172.18.0.1 - - [30/Sep/2025 18:22:00] "GET /_favicon.ico?v=3.0.4 HTTP/1.1" 200 -
dash-app-1  | 172.18.0.1 - - [30/Sep/2025 18:22:01] "GET /assets/logo.png HTTP/1.1" 304 -
dash-app-1  | 172.18.0.1 - - [30/Sep/2025 18:22:01] "POST /_dash-update-component HTTP/1.1" 200 -
dash-app-1  | 172.18.0.1 - - [30/Sep/2025 18:22:01] "GET /assets/wikimedia-logo.png HTTP/1.1" 304 -
dash-app-1  | [2025-09-30 18:22:02,214] ERROR in app: Exception on /_dash-update-component [POST]
dash-app-1  | Traceback (most recent call last):
dash-app-1  |   File "/usr/local/lib/python3.12/site-packages/flask/app.py", line 1473, in wsgi_app
dash-app-1  |     response = self.full_dispatch_request()
dash-app-1  |                ^^^^^^^^^^^^^^^^^^^^^^^^^^^^
dash-app-1  |   File "/usr/local/lib/python3.12/site-packages/flask/app.py", line 882, in full_dispatch_request
dash-app-1  |     rv = self.handle_user_exception(e)
dash-app-1  |          ^^^^^^^^^^^^^^^^^^^^^^^^^^^^^
dash-app-1  |   File "/usr/local/lib/python3.12/site-packages/flask/app.py", line 880, in full_dispatch_request
dash-app-1  |     rv = self.dispatch_request()
dash-app-1  |          ^^^^^^^^^^^^^^^^^^^^^^^
dash-app-1  |   File "/usr/local/lib/python3.12/site-packages/flask/app.py", line 865, in dispatch_request
dash-app-1  |     return self.ensure_sync(self.view_functions[rule.endpoint])(**view_args)  # type: ignore[no-any-return]
dash-app-1  |            ^^^^^^^^^^^^^^^^^^^^^^^^^^^^^^^^^^^^^^^^^^^^^^^^^^^^^^^^^^^^^^^^^
dash-app-1  |   File "/usr/local/lib/python3.12/site-packages/dash/dash.py", line 1414, in dispatch
dash-app-1  |     ctx.run(
dash-app-1  |   File "/usr/local/lib/python3.12/site-packages/dash/_callback.py", line 536, in add_context
dash-app-1  |     raise err
dash-app-1  |   File "/usr/local/lib/python3.12/site-packages/dash/_callback.py", line 525, in add_context
dash-app-1  |     output_value = _invoke_callback(func, *func_args, **func_kwargs)  # type: ignore[reportArgumentType]
dash-app-1  |                    ^^^^^^^^^^^^^^^^^^^^^^^^^^^^^^^^^^^^^^^^^^^^^^^^^
dash-app-1  |   File "/usr/local/lib/python3.12/site-packages/dash/_callback.py", line 47, in _invoke_callback
dash-app-1  |     return func(*args, **kwargs)  # %% callback invoked %%
dash-app-1  |            ^^^^^^^^^^^^^^^^^^^^^
dash-app-1  |   File "/app/apps/main_app.py", line 278, in page_load
dash-app-1  |     return main_app_build_layout(state)
dash-app-1  |            ^^^^^^^^^^^^^^^^^^^^^^^^^^^^
dash-app-1  |   File "/app/apps/main_app.py", line 294, in main_app_build_layout
dash-app-1  |     main_app.title = "Vital Signs"+title_addenda
dash-app-1  |     ^^^^^^^^
dash-app-1  | NameError: name 'main_app' is not defined
dash-app-1  | 172.18.0.1 - - [30/Sep/2025 18:22:02] "POST /_dash-update-component HTTP/1.1" 500 -
dash-app-1  | 172.18.0.1 - - [30/Sep/2025 18:22:02] "GET / HTTP/1.1" 200 -
dash-app-1  | 172.18.0.1 - - [30/Sep/2025 18:22:03] "GET /_dash-dependencies HTTP/1.1" 200 -
dash-app-1  | 172.18.0.1 - - [30/Sep/2025 18:22:03] "GET /_dash-layout HTTP/1.1" 200 -
dash-app-1  | 172.18.0.1 - - [30/Sep/2025 18:22:04] "POST /_dash-update-component HTTP/1.1" 200 -
dash-app-1  | 172.18.0.1 - - [30/Sep/2025 18:22:04] "GET /assets/wikimedia-logo.png HTTP/1.1" 304 -
dash-app-1  | 172.18.0.1 - - [30/Sep/2025 18:22:04] "GET /assets/logo.png HTTP/1.1" 304 -
dash-app-1  | 172.18.0.1 - - [30/Sep/2025 18:22:17] "POST /_dash-update-component HTTP/1.1" 200 -
dash-app-1  | 172.18.0.1 - - [30/Sep/2025 18:22:21] "GET /_dash-component-suites/dash/dcc/async-graph.js HTTP/1.1" 304 -
dash-app-1  | 172.18.0.1 - - [30/Sep/2025 18:22:21] "GET /_dash-component-suites/dash/dcc/async-dropdown.js HTTP/1.1" 304 -
dash-app-1  | 172.18.0.1 - - [30/Sep/2025 18:22:21] "GET /_dash-component-suites/plotly/package_data/plotly.min.js HTTP/1.1" 200 -
dash-app-1  | 172.18.0.1 - - [30/Sep/2025 18:22:21] "POST /_dash-update-component HTTP/1.1" 200 -
dash-app-1  | 172.18.0.1 - - [30/Sep/2025 18:22:21] "GET /_dash-component-suites/dash/dcc/async-markdown.js HTTP/1.1" 304 -
dash-app-1  | [2025-09-30 18:22:21,958] ERROR in app: Exception on /_dash-update-component [POST]
dash-app-1  | Traceback (most recent call last):
dash-app-1  |   File "/usr/local/lib/python3.12/site-packages/sqlalchemy/engine/base.py", line 146, in __init__
dash-app-1  |     self._dbapi_connection = engine.raw_connection()
dash-app-1  |                              ^^^^^^^^^^^^^^^^^^^^^^^
dash-app-1  |   File "/usr/local/lib/python3.12/site-packages/sqlalchemy/engine/base.py", line 3302, in raw_connection
dash-app-1  |     return self.pool.connect()
dash-app-1  |            ^^^^^^^^^^^^^^^^^^^
dash-app-1  |   File "/usr/local/lib/python3.12/site-packages/sqlalchemy/pool/base.py", line 449, in connect
dash-app-1  |     return _ConnectionFairy._checkout(self)
dash-app-1  |            ^^^^^^^^^^^^^^^^^^^^^^^^^^^^^^^^
dash-app-1  |   File "/usr/local/lib/python3.12/site-packages/sqlalchemy/pool/base.py", line 1263, in _checkout
dash-app-1  |     fairy = _ConnectionRecord.checkout(pool)
dash-app-1  |             ^^^^^^^^^^^^^^^^^^^^^^^^^^^^^^^^
dash-app-1  |   File "/usr/local/lib/python3.12/site-packages/sqlalchemy/pool/base.py", line 712, in checkout
dash-app-1  |     rec = pool._do_get()
dash-app-1  |           ^^^^^^^^^^^^^^
dash-app-1  |   File "/usr/local/lib/python3.12/site-packages/sqlalchemy/pool/impl.py", line 179, in _do_get
dash-app-1  |     with util.safe_reraise():
dash-app-1  |          ^^^^^^^^^^^^^^^^^^^
dash-app-1  |   File "/usr/local/lib/python3.12/site-packages/sqlalchemy/util/langhelpers.py", line 146, in __exit__
dash-app-1  |     raise exc_value.with_traceback(exc_tb)
dash-app-1  |   File "/usr/local/lib/python3.12/site-packages/sqlalchemy/pool/impl.py", line 177, in _do_get
dash-app-1  |     return self._create_connection()
dash-app-1  |            ^^^^^^^^^^^^^^^^^^^^^^^^^
dash-app-1  |   File "/usr/local/lib/python3.12/site-packages/sqlalchemy/pool/base.py", line 390, in _create_connection
dash-app-1  |     return _ConnectionRecord(self)
dash-app-1  |            ^^^^^^^^^^^^^^^^^^^^^^^
dash-app-1  |   File "/usr/local/lib/python3.12/site-packages/sqlalchemy/pool/base.py", line 674, in __init__
dash-app-1  |     self.__connect()
dash-app-1  |   File "/usr/local/lib/python3.12/site-packages/sqlalchemy/pool/base.py", line 900, in __connect
dash-app-1  |     with util.safe_reraise():
dash-app-1  |          ^^^^^^^^^^^^^^^^^^^
dash-app-1  |   File "/usr/local/lib/python3.12/site-packages/sqlalchemy/util/langhelpers.py", line 146, in __exit__
dash-app-1  |     raise exc_value.with_traceback(exc_tb)
dash-app-1  |   File "/usr/local/lib/python3.12/site-packages/sqlalchemy/pool/base.py", line 896, in __connect
dash-app-1  |     self.dbapi_connection = connection = pool._invoke_creator(self)
dash-app-1  |                                          ^^^^^^^^^^^^^^^^^^^^^^^^^^
dash-app-1  |   File "/usr/local/lib/python3.12/site-packages/sqlalchemy/engine/create.py", line 643, in connect
dash-app-1  |     return dialect.connect(*cargs, **cparams)
dash-app-1  |            ^^^^^^^^^^^^^^^^^^^^^^^^^^^^^^^^^^
dash-app-1  |   File "/usr/local/lib/python3.12/site-packages/sqlalchemy/engine/default.py", line 621, in connect
dash-app-1  |     return self.loaded_dbapi.connect(*cargs, **cparams)
dash-app-1  |            ^^^^^^^^^^^^^^^^^^^^^^^^^^^^^^^^^^^^^^^^^^^^
dash-app-1  |   File "/usr/local/lib/python3.12/site-packages/psycopg2/__init__.py", line 122, in connect
dash-app-1  |     conn = _connect(dsn, connection_factory=connection_factory, **kwasync)
dash-app-1  |            ^^^^^^^^^^^^^^^^^^^^^^^^^^^^^^^^^^^^^^^^^^^^^^^^^^^^^^^^^^^^^^^
dash-app-1  | psycopg2.OperationalError: connection to server at "postgres" (172.18.0.6), port 5432 failed: FATAL:  password authentication failed for user "None"
dash-app-1  | 
dash-app-1  | 
dash-app-1  | The above exception was the direct cause of the following exception:
dash-app-1  | 
dash-app-1  | Traceback (most recent call last):
dash-app-1  |   File "/usr/local/lib/python3.12/site-packages/flask/app.py", line 1473, in wsgi_app
dash-app-1  |     response = self.full_dispatch_request()
dash-app-1  |                ^^^^^^^^^^^^^^^^^^^^^^^^^^^^
dash-app-1  |   File "/usr/local/lib/python3.12/site-packages/flask/app.py", line 882, in full_dispatch_request
dash-app-1  |     rv = self.handle_user_exception(e)
dash-app-1  |          ^^^^^^^^^^^^^^^^^^^^^^^^^^^^^
dash-app-1  |   File "/usr/local/lib/python3.12/site-packages/flask/app.py", line 880, in full_dispatch_request
dash-app-1  |     rv = self.dispatch_request()
dash-app-1  |          ^^^^^^^^^^^^^^^^^^^^^^^
dash-app-1  |   File "/usr/local/lib/python3.12/site-packages/flask/app.py", line 865, in dispatch_request
dash-app-1  |     return self.ensure_sync(self.view_functions[rule.endpoint])(**view_args)  # type: ignore[no-any-return]
dash-app-1  |            ^^^^^^^^^^^^^^^^^^^^^^^^^^^^^^^^^^^^^^^^^^^^^^^^^^^^^^^^^^^^^^^^^
dash-app-1  |   File "/usr/local/lib/python3.12/site-packages/dash/dash.py", line 1414, in dispatch
dash-app-1  |     ctx.run(
dash-app-1  |   File "/usr/local/lib/python3.12/site-packages/dash/_callback.py", line 536, in add_context
dash-app-1  |     raise err
dash-app-1  |   File "/usr/local/lib/python3.12/site-packages/dash/_callback.py", line 525, in add_context
dash-app-1  |     output_value = _invoke_callback(func, *func_args, **func_kwargs)  # type: ignore[reportArgumentType]
dash-app-1  |                    ^^^^^^^^^^^^^^^^^^^^^^^^^^^^^^^^^^^^^^^^^^^^^^^^^
dash-app-1  |   File "/usr/local/lib/python3.12/site-packages/dash/_callback.py", line 47, in _invoke_callback
dash-app-1  |     return func(*args, **kwargs)  # %% callback invoked %%
dash-app-1  |            ^^^^^^^^^^^^^^^^^^^^^
dash-app-1  |   File "/app/apps/activity.py", line 494, in update_graph
dash-app-1  |     df = pd.read_sql_query(query, engine)
dash-app-1  |          ^^^^^^^^^^^^^^^^^^^^^^^^^^^^^^^^
dash-app-1  |   File "/usr/local/lib/python3.12/site-packages/pandas/io/sql.py", line 525, in read_sql_query
dash-app-1  |     with pandasSQL_builder(con) as pandas_sql:
dash-app-1  |          ^^^^^^^^^^^^^^^^^^^^^^
dash-app-1  |   File "/usr/local/lib/python3.12/site-packages/pandas/io/sql.py", line 906, in pandasSQL_builder
dash-app-1  |     return SQLDatabase(con, schema, need_transaction)
dash-app-1  |            ^^^^^^^^^^^^^^^^^^^^^^^^^^^^^^^^^^^^^^^^^^
dash-app-1  |   File "/usr/local/lib/python3.12/site-packages/pandas/io/sql.py", line 1636, in __init__
dash-app-1  |     con = self.exit_stack.enter_context(con.connect())
dash-app-1  |                                         ^^^^^^^^^^^^^
dash-app-1  |   File "/usr/local/lib/python3.12/site-packages/sqlalchemy/engine/base.py", line 3278, in connect
dash-app-1  |     return self._connection_cls(self)
dash-app-1  |            ^^^^^^^^^^^^^^^^^^^^^^^^^^
dash-app-1  |   File "/usr/local/lib/python3.12/site-packages/sqlalchemy/engine/base.py", line 148, in __init__
dash-app-1  |     Connection._handle_dbapi_exception_noconnection(
dash-app-1  |   File "/usr/local/lib/python3.12/site-packages/sqlalchemy/engine/base.py", line 2442, in _handle_dbapi_exception_noconnection
dash-app-1  |     raise sqlalchemy_exception.with_traceback(exc_info[2]) from e
dash-app-1  |   File "/usr/local/lib/python3.12/site-packages/sqlalchemy/engine/base.py", line 146, in __init__
dash-app-1  |     self._dbapi_connection = engine.raw_connection()
dash-app-1  |                              ^^^^^^^^^^^^^^^^^^^^^^^
dash-app-1  |   File "/usr/local/lib/python3.12/site-packages/sqlalchemy/engine/base.py", line 3302, in raw_connection
dash-app-1  |     return self.pool.connect()
dash-app-1  |            ^^^^^^^^^^^^^^^^^^^
dash-app-1  |   File "/usr/local/lib/python3.12/site-packages/sqlalchemy/pool/base.py", line 449, in connect
dash-app-1  |     return _ConnectionFairy._checkout(self)
dash-app-1  |            ^^^^^^^^^^^^^^^^^^^^^^^^^^^^^^^^
dash-app-1  |   File "/usr/local/lib/python3.12/site-packages/sqlalchemy/pool/base.py", line 1263, in _checkout
dash-app-1  |     fairy = _ConnectionRecord.checkout(pool)
dash-app-1  |             ^^^^^^^^^^^^^^^^^^^^^^^^^^^^^^^^
dash-app-1  |   File "/usr/local/lib/python3.12/site-packages/sqlalchemy/pool/base.py", line 712, in checkout
dash-app-1  |     rec = pool._do_get()
dash-app-1  |           ^^^^^^^^^^^^^^
dash-app-1  |   File "/usr/local/lib/python3.12/site-packages/sqlalchemy/pool/impl.py", line 179, in _do_get
dash-app-1  |     with util.safe_reraise():
dash-app-1  |          ^^^^^^^^^^^^^^^^^^^
dash-app-1  |   File "/usr/local/lib/python3.12/site-packages/sqlalchemy/util/langhelpers.py", line 146, in __exit__
dash-app-1  |     raise exc_value.with_traceback(exc_tb)
dash-app-1  |   File "/usr/local/lib/python3.12/site-packages/sqlalchemy/pool/impl.py", line 177, in _do_get
dash-app-1  |     return self._create_connection()
dash-app-1  |            ^^^^^^^^^^^^^^^^^^^^^^^^^
dash-app-1  |   File "/usr/local/lib/python3.12/site-packages/sqlalchemy/pool/base.py", line 390, in _create_connection
dash-app-1  |     return _ConnectionRecord(self)
dash-app-1  |            ^^^^^^^^^^^^^^^^^^^^^^^
dash-app-1  |   File "/usr/local/lib/python3.12/site-packages/sqlalchemy/pool/base.py", line 674, in __init__
dash-app-1  |     self.__connect()
dash-app-1  |   File "/usr/local/lib/python3.12/site-packages/sqlalchemy/pool/base.py", line 900, in __connect
dash-app-1  |     with util.safe_reraise():
dash-app-1  |          ^^^^^^^^^^^^^^^^^^^
dash-app-1  |   File "/usr/local/lib/python3.12/site-packages/sqlalchemy/util/langhelpers.py", line 146, in __exit__
dash-app-1  |     raise exc_value.with_traceback(exc_tb)
dash-app-1  |   File "/usr/local/lib/python3.12/site-packages/sqlalchemy/pool/base.py", line 896, in __connect
dash-app-1  |     self.dbapi_connection = connection = pool._invoke_creator(self)
dash-app-1  |                                          ^^^^^^^^^^^^^^^^^^^^^^^^^^
dash-app-1  |   File "/usr/local/lib/python3.12/site-packages/sqlalchemy/engine/create.py", line 643, in connect
dash-app-1  |     return dialect.connect(*cargs, **cparams)
dash-app-1  |            ^^^^^^^^^^^^^^^^^^^^^^^^^^^^^^^^^^
dash-app-1  |   File "/usr/local/lib/python3.12/site-packages/sqlalchemy/engine/default.py", line 621, in connect
dash-app-1  |     return self.loaded_dbapi.connect(*cargs, **cparams)
dash-app-1  |            ^^^^^^^^^^^^^^^^^^^^^^^^^^^^^^^^^^^^^^^^^^^^
dash-app-1  |   File "/usr/local/lib/python3.12/site-packages/psycopg2/__init__.py", line 122, in connect
dash-app-1  |     conn = _connect(dsn, connection_factory=connection_factory, **kwasync)
dash-app-1  |            ^^^^^^^^^^^^^^^^^^^^^^^^^^^^^^^^^^^^^^^^^^^^^^^^^^^^^^^^^^^^^^^
dash-app-1  | sqlalchemy.exc.OperationalError: (psycopg2.OperationalError) connection to server at "postgres" (172.18.0.6), port 5432 failed: FATAL:  password authentication failed for user "None"
dash-app-1  | 
dash-app-1  | (Background on this error at: https://sqlalche.me/e/20/e3q8)
dash-app-1  | 172.18.0.1 - - [30/Sep/2025 18:22:21] "POST /_dash-update-component HTTP/1.1" 500 -
dash-app-1  | [2025-09-30 18:24:26,805] ERROR in app: Exception on /_dash-update-component [POST]
dash-app-1  | Traceback (most recent call last):
dash-app-1  |   File "/usr/local/lib/python3.12/site-packages/flask/app.py", line 1473, in wsgi_app
dash-app-1  |     response = self.full_dispatch_request()
dash-app-1  |                ^^^^^^^^^^^^^^^^^^^^^^^^^^^^
dash-app-1  |   File "/usr/local/lib/python3.12/site-packages/flask/app.py", line 882, in full_dispatch_request
dash-app-1  |     rv = self.handle_user_exception(e)
dash-app-1  |          ^^^^^^^^^^^^^^^^^^^^^^^^^^^^^
dash-app-1  |   File "/usr/local/lib/python3.12/site-packages/flask/app.py", line 880, in full_dispatch_request
dash-app-1  |     rv = self.dispatch_request()
dash-app-1  |          ^^^^^^^^^^^^^^^^^^^^^^^
dash-app-1  |   File "/usr/local/lib/python3.12/site-packages/flask/app.py", line 865, in dispatch_request
dash-app-1  |     return self.ensure_sync(self.view_functions[rule.endpoint])(**view_args)  # type: ignore[no-any-return]
dash-app-1  |            ^^^^^^^^^^^^^^^^^^^^^^^^^^^^^^^^^^^^^^^^^^^^^^^^^^^^^^^^^^^^^^^^^
dash-app-1  |   File "/usr/local/lib/python3.12/site-packages/dash/dash.py", line 1414, in dispatch
dash-app-1  |     ctx.run(
dash-app-1  |   File "/usr/local/lib/python3.12/site-packages/dash/_callback.py", line 536, in add_context
dash-app-1  |     raise err
dash-app-1  |   File "/usr/local/lib/python3.12/site-packages/dash/_callback.py", line 525, in add_context
dash-app-1  |     output_value = _invoke_callback(func, *func_args, **func_kwargs)  # type: ignore[reportArgumentType]
dash-app-1  |                    ^^^^^^^^^^^^^^^^^^^^^^^^^^^^^^^^^^^^^^^^^^^^^^^^^
dash-app-1  |   File "/usr/local/lib/python3.12/site-packages/dash/_callback.py", line 47, in _invoke_callback
dash-app-1  |     return func(*args, **kwargs)  # %% callback invoked %%
dash-app-1  |            ^^^^^^^^^^^^^^^^^^^^^
dash-app-1  |   File "/app/apps/activity.py", line 308, in page_load
dash-app-1  |     print(state["langcode"])
dash-app-1  |           ~~~~~^^^^^^^^^^^^
dash-app-1  | KeyError: 'langcode'
dash-app-1  | 172.18.0.1 - - [30/Sep/2025 18:24:26] "POST /_dash-update-component HTTP/1.1" 500 -
dash-app-1  | [2025-09-30 18:24:26,837] ERROR in app: Exception on /_dash-update-component [POST]
dash-app-1  | Traceback (most recent call last):
dash-app-1  |   File "/usr/local/lib/python3.12/site-packages/sqlalchemy/engine/base.py", line 146, in __init__
dash-app-1  |     self._dbapi_connection = engine.raw_connection()
dash-app-1  |                              ^^^^^^^^^^^^^^^^^^^^^^^
dash-app-1  |   File "/usr/local/lib/python3.12/site-packages/sqlalchemy/engine/base.py", line 3302, in raw_connection
dash-app-1  |     return self.pool.connect()
dash-app-1  |            ^^^^^^^^^^^^^^^^^^^
dash-app-1  |   File "/usr/local/lib/python3.12/site-packages/sqlalchemy/pool/base.py", line 449, in connect
dash-app-1  |     return _ConnectionFairy._checkout(self)
dash-app-1  |            ^^^^^^^^^^^^^^^^^^^^^^^^^^^^^^^^
dash-app-1  |   File "/usr/local/lib/python3.12/site-packages/sqlalchemy/pool/base.py", line 1263, in _checkout
dash-app-1  |     fairy = _ConnectionRecord.checkout(pool)
dash-app-1  |             ^^^^^^^^^^^^^^^^^^^^^^^^^^^^^^^^
dash-app-1  |   File "/usr/local/lib/python3.12/site-packages/sqlalchemy/pool/base.py", line 712, in checkout
dash-app-1  |     rec = pool._do_get()
dash-app-1  |           ^^^^^^^^^^^^^^
dash-app-1  |   File "/usr/local/lib/python3.12/site-packages/sqlalchemy/pool/impl.py", line 179, in _do_get
dash-app-1  |     with util.safe_reraise():
dash-app-1  |          ^^^^^^^^^^^^^^^^^^^
dash-app-1  |   File "/usr/local/lib/python3.12/site-packages/sqlalchemy/util/langhelpers.py", line 146, in __exit__
dash-app-1  |     raise exc_value.with_traceback(exc_tb)
dash-app-1  |   File "/usr/local/lib/python3.12/site-packages/sqlalchemy/pool/impl.py", line 177, in _do_get
dash-app-1  |     return self._create_connection()
dash-app-1  |            ^^^^^^^^^^^^^^^^^^^^^^^^^
dash-app-1  |   File "/usr/local/lib/python3.12/site-packages/sqlalchemy/pool/base.py", line 390, in _create_connection
dash-app-1  |     return _ConnectionRecord(self)
dash-app-1  |            ^^^^^^^^^^^^^^^^^^^^^^^
dash-app-1  |   File "/usr/local/lib/python3.12/site-packages/sqlalchemy/pool/base.py", line 674, in __init__
dash-app-1  |     self.__connect()
dash-app-1  |   File "/usr/local/lib/python3.12/site-packages/sqlalchemy/pool/base.py", line 900, in __connect
dash-app-1  |     with util.safe_reraise():
dash-app-1  |          ^^^^^^^^^^^^^^^^^^^
dash-app-1  |   File "/usr/local/lib/python3.12/site-packages/sqlalchemy/util/langhelpers.py", line 146, in __exit__
dash-app-1  |     raise exc_value.with_traceback(exc_tb)
dash-app-1  |   File "/usr/local/lib/python3.12/site-packages/sqlalchemy/pool/base.py", line 896, in __connect
dash-app-1  |     self.dbapi_connection = connection = pool._invoke_creator(self)
dash-app-1  |                                          ^^^^^^^^^^^^^^^^^^^^^^^^^^
dash-app-1  |   File "/usr/local/lib/python3.12/site-packages/sqlalchemy/engine/create.py", line 643, in connect
dash-app-1  |     return dialect.connect(*cargs, **cparams)
dash-app-1  |            ^^^^^^^^^^^^^^^^^^^^^^^^^^^^^^^^^^
dash-app-1  |   File "/usr/local/lib/python3.12/site-packages/sqlalchemy/engine/default.py", line 621, in connect
dash-app-1  |     return self.loaded_dbapi.connect(*cargs, **cparams)
dash-app-1  |            ^^^^^^^^^^^^^^^^^^^^^^^^^^^^^^^^^^^^^^^^^^^^
dash-app-1  |   File "/usr/local/lib/python3.12/site-packages/psycopg2/__init__.py", line 122, in connect
dash-app-1  |     conn = _connect(dsn, connection_factory=connection_factory, **kwasync)
dash-app-1  |            ^^^^^^^^^^^^^^^^^^^^^^^^^^^^^^^^^^^^^^^^^^^^^^^^^^^^^^^^^^^^^^^
dash-app-1  | psycopg2.OperationalError: connection to server at "postgres" (172.18.0.6), port 5432 failed: FATAL:  password authentication failed for user "None"
dash-app-1  | 
dash-app-1  | 
dash-app-1  | The above exception was the direct cause of the following exception:
dash-app-1  | 
dash-app-1  | Traceback (most recent call last):
dash-app-1  |   File "/usr/local/lib/python3.12/site-packages/flask/app.py", line 1473, in wsgi_app
dash-app-1  |     response = self.full_dispatch_request()
dash-app-1  |                ^^^^^^^^^^^^^^^^^^^^^^^^^^^^
dash-app-1  |   File "/usr/local/lib/python3.12/site-packages/flask/app.py", line 882, in full_dispatch_request
dash-app-1  |     rv = self.handle_user_exception(e)
dash-app-1  |          ^^^^^^^^^^^^^^^^^^^^^^^^^^^^^
dash-app-1  |   File "/usr/local/lib/python3.12/site-packages/flask/app.py", line 880, in full_dispatch_request
dash-app-1  |     rv = self.dispatch_request()
dash-app-1  |          ^^^^^^^^^^^^^^^^^^^^^^^
dash-app-1  |   File "/usr/local/lib/python3.12/site-packages/flask/app.py", line 865, in dispatch_request
dash-app-1  |     return self.ensure_sync(self.view_functions[rule.endpoint])(**view_args)  # type: ignore[no-any-return]
dash-app-1  |            ^^^^^^^^^^^^^^^^^^^^^^^^^^^^^^^^^^^^^^^^^^^^^^^^^^^^^^^^^^^^^^^^^
dash-app-1  |   File "/usr/local/lib/python3.12/site-packages/dash/dash.py", line 1414, in dispatch
dash-app-1  |     ctx.run(
dash-app-1  |   File "/usr/local/lib/python3.12/site-packages/dash/_callback.py", line 536, in add_context
dash-app-1  |     raise err
dash-app-1  |   File "/usr/local/lib/python3.12/site-packages/dash/_callback.py", line 525, in add_context
dash-app-1  |     output_value = _invoke_callback(func, *func_args, **func_kwargs)  # type: ignore[reportArgumentType]
dash-app-1  |                    ^^^^^^^^^^^^^^^^^^^^^^^^^^^^^^^^^^^^^^^^^^^^^^^^^
dash-app-1  |   File "/usr/local/lib/python3.12/site-packages/dash/_callback.py", line 47, in _invoke_callback
dash-app-1  |     return func(*args, **kwargs)  # %% callback invoked %%
dash-app-1  |            ^^^^^^^^^^^^^^^^^^^^^
dash-app-1  |   File "/app/apps/activity.py", line 419, in highlights
dash-app-1  |     df1 = generate1(params, user_type, time_type, last5, engine)
dash-app-1  |           ^^^^^^^^^^^^^^^^^^^^^^^^^^^^^^^^^^^^^^^^^^^^^^^^^^^^^^
dash-app-1  |   File "/app/apps/activity.py", line 168, in generate1
dash-app-1  |     df1 = pd.read_sql_query(query2, engine)
dash-app-1  |           ^^^^^^^^^^^^^^^^^^^^^^^^^^^^^^^^^
dash-app-1  |   File "/usr/local/lib/python3.12/site-packages/pandas/io/sql.py", line 525, in read_sql_query
dash-app-1  |     with pandasSQL_builder(con) as pandas_sql:
dash-app-1  |          ^^^^^^^^^^^^^^^^^^^^^^
dash-app-1  |   File "/usr/local/lib/python3.12/site-packages/pandas/io/sql.py", line 906, in pandasSQL_builder
dash-app-1  |     return SQLDatabase(con, schema, need_transaction)
dash-app-1  |            ^^^^^^^^^^^^^^^^^^^^^^^^^^^^^^^^^^^^^^^^^^
dash-app-1  |   File "/usr/local/lib/python3.12/site-packages/pandas/io/sql.py", line 1636, in __init__
dash-app-1  |     con = self.exit_stack.enter_context(con.connect())
dash-app-1  |                                         ^^^^^^^^^^^^^
dash-app-1  |   File "/usr/local/lib/python3.12/site-packages/sqlalchemy/engine/base.py", line 3278, in connect
dash-app-1  |     return self._connection_cls(self)
dash-app-1  |            ^^^^^^^^^^^^^^^^^^^^^^^^^^
dash-app-1  |   File "/usr/local/lib/python3.12/site-packages/sqlalchemy/engine/base.py", line 148, in __init__
dash-app-1  |     Connection._handle_dbapi_exception_noconnection(
dash-app-1  |   File "/usr/local/lib/python3.12/site-packages/sqlalchemy/engine/base.py", line 2442, in _handle_dbapi_exception_noconnection
dash-app-1  |     raise sqlalchemy_exception.with_traceback(exc_info[2]) from e
dash-app-1  |   File "/usr/local/lib/python3.12/site-packages/sqlalchemy/engine/base.py", line 146, in __init__
dash-app-1  |     self._dbapi_connection = engine.raw_connection()
dash-app-1  |                              ^^^^^^^^^^^^^^^^^^^^^^^
dash-app-1  |   File "/usr/local/lib/python3.12/site-packages/sqlalchemy/engine/base.py", line 3302, in raw_connection
dash-app-1  |     return self.pool.connect()
dash-app-1  |            ^^^^^^^^^^^^^^^^^^^
dash-app-1  |   File "/usr/local/lib/python3.12/site-packages/sqlalchemy/pool/base.py", line 449, in connect
dash-app-1  |     return _ConnectionFairy._checkout(self)
dash-app-1  |            ^^^^^^^^^^^^^^^^^^^^^^^^^^^^^^^^
dash-app-1  |   File "/usr/local/lib/python3.12/site-packages/sqlalchemy/pool/base.py", line 1263, in _checkout
dash-app-1  |     fairy = _ConnectionRecord.checkout(pool)
dash-app-1  |             ^^^^^^^^^^^^^^^^^^^^^^^^^^^^^^^^
dash-app-1  |   File "/usr/local/lib/python3.12/site-packages/sqlalchemy/pool/base.py", line 712, in checkout
dash-app-1  |     rec = pool._do_get()
dash-app-1  |           ^^^^^^^^^^^^^^
dash-app-1  |   File "/usr/local/lib/python3.12/site-packages/sqlalchemy/pool/impl.py", line 179, in _do_get
dash-app-1  |     with util.safe_reraise():
dash-app-1  |          ^^^^^^^^^^^^^^^^^^^
dash-app-1  |   File "/usr/local/lib/python3.12/site-packages/sqlalchemy/util/langhelpers.py", line 146, in __exit__
dash-app-1  |     raise exc_value.with_traceback(exc_tb)
dash-app-1  |   File "/usr/local/lib/python3.12/site-packages/sqlalchemy/pool/impl.py", line 177, in _do_get
dash-app-1  |     return self._create_connection()
dash-app-1  |            ^^^^^^^^^^^^^^^^^^^^^^^^^
dash-app-1  |   File "/usr/local/lib/python3.12/site-packages/sqlalchemy/pool/base.py", line 390, in _create_connection
dash-app-1  |     return _ConnectionRecord(self)
dash-app-1  |            ^^^^^^^^^^^^^^^^^^^^^^^
dash-app-1  |   File "/usr/local/lib/python3.12/site-packages/sqlalchemy/pool/base.py", line 674, in __init__
dash-app-1  |     self.__connect()
dash-app-1  |   File "/usr/local/lib/python3.12/site-packages/sqlalchemy/pool/base.py", line 900, in __connect
dash-app-1  |     with util.safe_reraise():
dash-app-1  |          ^^^^^^^^^^^^^^^^^^^
dash-app-1  |   File "/usr/local/lib/python3.12/site-packages/sqlalchemy/util/langhelpers.py", line 146, in __exit__
dash-app-1  |     raise exc_value.with_traceback(exc_tb)
dash-app-1  |   File "/usr/local/lib/python3.12/site-packages/sqlalchemy/pool/base.py", line 896, in __connect
dash-app-1  |     self.dbapi_connection = connection = pool._invoke_creator(self)
dash-app-1  |                                          ^^^^^^^^^^^^^^^^^^^^^^^^^^
dash-app-1  |   File "/usr/local/lib/python3.12/site-packages/sqlalchemy/engine/create.py", line 643, in connect
dash-app-1  |     return dialect.connect(*cargs, **cparams)
dash-app-1  |            ^^^^^^^^^^^^^^^^^^^^^^^^^^^^^^^^^^
dash-app-1  |   File "/usr/local/lib/python3.12/site-packages/sqlalchemy/engine/default.py", line 621, in connect
dash-app-1  |     return self.loaded_dbapi.connect(*cargs, **cparams)
dash-app-1  |            ^^^^^^^^^^^^^^^^^^^^^^^^^^^^^^^^^^^^^^^^^^^^
dash-app-1  |   File "/usr/local/lib/python3.12/site-packages/psycopg2/__init__.py", line 122, in connect
dash-app-1  |     conn = _connect(dsn, connection_factory=connection_factory, **kwasync)
dash-app-1  |            ^^^^^^^^^^^^^^^^^^^^^^^^^^^^^^^^^^^^^^^^^^^^^^^^^^^^^^^^^^^^^^^
dash-app-1  | sqlalchemy.exc.OperationalError: (psycopg2.OperationalError) connection to server at "postgres" (172.18.0.6), port 5432 failed: FATAL:  password authentication failed for user "None"
dash-app-1  | 
dash-app-1  | (Background on this error at: https://sqlalche.me/e/20/e3q8)
dash-app-1  | 172.18.0.1 - - [30/Sep/2025 18:24:26] "POST /_dash-update-component HTTP/1.1" 500 -
dash-app-1  | 172.18.0.1 - - [30/Sep/2025 18:24:31] "GET / HTTP/1.1" 200 -
dash-app-1  | 172.18.0.1 - - [30/Sep/2025 18:24:32] "POST /_dash-update-component HTTP/1.1" 200 -
dash-app-1  | [2025-09-30 18:24:32,051] ERROR in app: Exception on /_dash-update-component [POST]
dash-app-1  | Traceback (most recent call last):
dash-app-1  |   File "/usr/local/lib/python3.12/site-packages/flask/app.py", line 1473, in wsgi_app
dash-app-1  |     response = self.full_dispatch_request()
dash-app-1  |                ^^^^^^^^^^^^^^^^^^^^^^^^^^^^
dash-app-1  |   File "/usr/local/lib/python3.12/site-packages/flask/app.py", line 882, in full_dispatch_request
dash-app-1  |     rv = self.handle_user_exception(e)
dash-app-1  |          ^^^^^^^^^^^^^^^^^^^^^^^^^^^^^
dash-app-1  |   File "/usr/local/lib/python3.12/site-packages/flask/app.py", line 880, in full_dispatch_request
dash-app-1  |     rv = self.dispatch_request()
dash-app-1  |          ^^^^^^^^^^^^^^^^^^^^^^^
dash-app-1  |   File "/usr/local/lib/python3.12/site-packages/flask/app.py", line 865, in dispatch_request
dash-app-1  |     return self.ensure_sync(self.view_functions[rule.endpoint])(**view_args)  # type: ignore[no-any-return]
dash-app-1  |            ^^^^^^^^^^^^^^^^^^^^^^^^^^^^^^^^^^^^^^^^^^^^^^^^^^^^^^^^^^^^^^^^^
dash-app-1  |   File "/usr/local/lib/python3.12/site-packages/dash/dash.py", line 1414, in dispatch
dash-app-1  |     ctx.run(
dash-app-1  |   File "/usr/local/lib/python3.12/site-packages/dash/_callback.py", line 536, in add_context
dash-app-1  |     raise err
dash-app-1  |   File "/usr/local/lib/python3.12/site-packages/dash/_callback.py", line 525, in add_context
dash-app-1  |     output_value = _invoke_callback(func, *func_args, **func_kwargs)  # type: ignore[reportArgumentType]
dash-app-1  |                    ^^^^^^^^^^^^^^^^^^^^^^^^^^^^^^^^^^^^^^^^^^^^^^^^^
dash-app-1  |   File "/usr/local/lib/python3.12/site-packages/dash/_callback.py", line 47, in _invoke_callback
dash-app-1  |     return func(*args, **kwargs)  # %% callback invoked %%
dash-app-1  |            ^^^^^^^^^^^^^^^^^^^^^
dash-app-1  |   File "/app/apps/activity.py", line 308, in page_load
dash-app-1  |     print(state["langcode"])
dash-app-1  |           ~~~~~^^^^^^^^^^^^
dash-app-1  | KeyError: 'langcode'
dash-app-1  | 172.18.0.1 - - [30/Sep/2025 18:24:32] "POST /_dash-update-component HTTP/1.1" 500 -
dash-app-1  | 172.18.0.1 - - [30/Sep/2025 18:24:32] "POST /_dash-update-component HTTP/1.1" 200 -
dash-app-1  | [2025-09-30 18:24:32,480] ERROR in app: Exception on /_dash-update-component [POST]
dash-app-1  | Traceback (most recent call last):
dash-app-1  |   File "/usr/local/lib/python3.12/site-packages/flask/app.py", line 1473, in wsgi_app
dash-app-1  |     response = self.full_dispatch_request()
dash-app-1  |                ^^^^^^^^^^^^^^^^^^^^^^^^^^^^
dash-app-1  |   File "/usr/local/lib/python3.12/site-packages/flask/app.py", line 882, in full_dispatch_request
dash-app-1  |     rv = self.handle_user_exception(e)
dash-app-1  |          ^^^^^^^^^^^^^^^^^^^^^^^^^^^^^
dash-app-1  |   File "/usr/local/lib/python3.12/site-packages/flask/app.py", line 880, in full_dispatch_request
dash-app-1  |     rv = self.dispatch_request()
dash-app-1  |          ^^^^^^^^^^^^^^^^^^^^^^^
dash-app-1  |   File "/usr/local/lib/python3.12/site-packages/flask/app.py", line 865, in dispatch_request
dash-app-1  |     return self.ensure_sync(self.view_functions[rule.endpoint])(**view_args)  # type: ignore[no-any-return]
dash-app-1  |            ^^^^^^^^^^^^^^^^^^^^^^^^^^^^^^^^^^^^^^^^^^^^^^^^^^^^^^^^^^^^^^^^^
dash-app-1  |   File "/usr/local/lib/python3.12/site-packages/dash/dash.py", line 1414, in dispatch
dash-app-1  |     ctx.run(
dash-app-1  |   File "/usr/local/lib/python3.12/site-packages/dash/_callback.py", line 536, in add_context
dash-app-1  |     raise err
dash-app-1  |   File "/usr/local/lib/python3.12/site-packages/dash/_callback.py", line 525, in add_context
dash-app-1  |     output_value = _invoke_callback(func, *func_args, **func_kwargs)  # type: ignore[reportArgumentType]
dash-app-1  |                    ^^^^^^^^^^^^^^^^^^^^^^^^^^^^^^^^^^^^^^^^^^^^^^^^^
dash-app-1  |   File "/usr/local/lib/python3.12/site-packages/dash/_callback.py", line 47, in _invoke_callback
dash-app-1  |     return func(*args, **kwargs)  # %% callback invoked %%
dash-app-1  |            ^^^^^^^^^^^^^^^^^^^^^
dash-app-1  |   File "/app/apps/activity.py", line 308, in page_load
dash-app-1  |     print(state["langcode"])
dash-app-1  |           ~~~~~^^^^^^^^^^^^
dash-app-1  | KeyError: 'langcode'
dash-app-1  | 172.18.0.1 - - [30/Sep/2025 18:24:32] "POST /_dash-update-component HTTP/1.1" 500 -
dash-app-1  | 172.18.0.1 - - [30/Sep/2025 18:24:32] "GET /_dash-layout HTTP/1.1" 200 -
dash-app-1  | 172.18.0.1 - - [30/Sep/2025 18:24:32] "GET /_dash-dependencies HTTP/1.1" 200 -
dash-app-1  | 172.18.0.1 - - [30/Sep/2025 18:24:33] "GET /assets/logo.png HTTP/1.1" 304 -
dash-app-1  | 172.18.0.1 - - [30/Sep/2025 18:24:33] "GET /assets/wikimedia-logo.png HTTP/1.1" 304 -
dash-app-1  | 172.18.0.1 - - [30/Sep/2025 18:24:36] "POST /_dash-update-component HTTP/1.1" 200 -
dash-app-1  | 172.18.0.1 - - [01/Oct/2025 11:03:45] "GET / HTTP/1.1" 200 -
dash-app-1  | 172.18.0.1 - - [01/Oct/2025 11:03:46] "GET /_dash-layout HTTP/1.1" 200 -
dash-app-1  | 172.18.0.1 - - [01/Oct/2025 11:03:46] "GET /_dash-dependencies HTTP/1.1" 200 -
dash-app-1  | 172.18.0.1 - - [01/Oct/2025 11:03:47] "POST /_dash-update-component HTTP/1.1" 200 -
dash-app-1  | 172.18.0.1 - - [01/Oct/2025 11:03:47] "GET /assets/wikimedia-logo.png HTTP/1.1" 304 -
dash-app-1  | 172.18.0.1 - - [01/Oct/2025 11:03:47] "GET /assets/logo.png HTTP/1.1" 304 -
dash-app-1  | 172.18.0.1 - - [01/Oct/2025 11:03:49] "GET /main HTTP/1.1" 200 -
dash-app-1  | 172.18.0.1 - - [01/Oct/2025 11:03:50] "GET /_dash-layout HTTP/1.1" 200 -
dash-app-1  | 172.18.0.1 - - [01/Oct/2025 11:03:50] "GET /_dash-dependencies HTTP/1.1" 200 -
dash-app-1  | 172.18.0.1 - - [01/Oct/2025 11:03:51] "POST /_dash-update-component HTTP/1.1" 200 -
dash-app-1  | 172.18.0.1 - - [01/Oct/2025 11:03:51] "GET /assets/logo.png HTTP/1.1" 304 -
dash-app-1  | 172.18.0.1 - - [01/Oct/2025 11:03:51] "GET /assets/wikimedia-logo.png HTTP/1.1" 304 -
dash-app-1  | 172.18.0.1 - - [01/Oct/2025 11:03:52] "POST /_dash-update-component HTTP/1.1" 200 -
dash-app-1  | 172.18.0.1 - - [01/Oct/2025 11:03:52] "POST /_dash-update-component HTTP/1.1" 200 -
dash-app-1  | 172.18.0.1 - - [01/Oct/2025 11:03:52] "GET /_dash-component-suites/dash/dcc/async-dropdown.js HTTP/1.1" 304 -
dash-app-1  | 172.18.0.1 - - [01/Oct/2025 11:03:52] "GET /_dash-component-suites/dash/dcc/async-markdown.js HTTP/1.1" 304 -
dash-app-1  | [2025-10-01 11:03:52,937] ERROR in app: Exception on /_dash-update-component [POST]
dash-app-1  | Traceback (most recent call last):
dash-app-1  |   File "/usr/local/lib/python3.12/site-packages/sqlalchemy/engine/base.py", line 146, in __init__
dash-app-1  |     self._dbapi_connection = engine.raw_connection()
dash-app-1  |                              ^^^^^^^^^^^^^^^^^^^^^^^
dash-app-1  |   File "/usr/local/lib/python3.12/site-packages/sqlalchemy/engine/base.py", line 3302, in raw_connection
dash-app-1  |     return self.pool.connect()
dash-app-1  |            ^^^^^^^^^^^^^^^^^^^
dash-app-1  |   File "/usr/local/lib/python3.12/site-packages/sqlalchemy/pool/base.py", line 449, in connect
dash-app-1  |     return _ConnectionFairy._checkout(self)
dash-app-1  |            ^^^^^^^^^^^^^^^^^^^^^^^^^^^^^^^^
dash-app-1  |   File "/usr/local/lib/python3.12/site-packages/sqlalchemy/pool/base.py", line 1263, in _checkout
dash-app-1  |     fairy = _ConnectionRecord.checkout(pool)
dash-app-1  |             ^^^^^^^^^^^^^^^^^^^^^^^^^^^^^^^^
dash-app-1  |   File "/usr/local/lib/python3.12/site-packages/sqlalchemy/pool/base.py", line 712, in checkout
dash-app-1  |     rec = pool._do_get()
dash-app-1  |           ^^^^^^^^^^^^^^
dash-app-1  |   File "/usr/local/lib/python3.12/site-packages/sqlalchemy/pool/impl.py", line 179, in _do_get
dash-app-1  |     with util.safe_reraise():
dash-app-1  |          ^^^^^^^^^^^^^^^^^^^
dash-app-1  |   File "/usr/local/lib/python3.12/site-packages/sqlalchemy/util/langhelpers.py", line 146, in __exit__
dash-app-1  |     raise exc_value.with_traceback(exc_tb)
dash-app-1  |   File "/usr/local/lib/python3.12/site-packages/sqlalchemy/pool/impl.py", line 177, in _do_get
dash-app-1  |     return self._create_connection()
dash-app-1  |            ^^^^^^^^^^^^^^^^^^^^^^^^^
dash-app-1  |   File "/usr/local/lib/python3.12/site-packages/sqlalchemy/pool/base.py", line 390, in _create_connection
dash-app-1  |     return _ConnectionRecord(self)
dash-app-1  |            ^^^^^^^^^^^^^^^^^^^^^^^
dash-app-1  |   File "/usr/local/lib/python3.12/site-packages/sqlalchemy/pool/base.py", line 674, in __init__
dash-app-1  |     self.__connect()
dash-app-1  |   File "/usr/local/lib/python3.12/site-packages/sqlalchemy/pool/base.py", line 900, in __connect
dash-app-1  |     with util.safe_reraise():
dash-app-1  |          ^^^^^^^^^^^^^^^^^^^
dash-app-1  |   File "/usr/local/lib/python3.12/site-packages/sqlalchemy/util/langhelpers.py", line 146, in __exit__
dash-app-1  |     raise exc_value.with_traceback(exc_tb)
dash-app-1  |   File "/usr/local/lib/python3.12/site-packages/sqlalchemy/pool/base.py", line 896, in __connect
dash-app-1  |     self.dbapi_connection = connection = pool._invoke_creator(self)
dash-app-1  |                                          ^^^^^^^^^^^^^^^^^^^^^^^^^^
dash-app-1  |   File "/usr/local/lib/python3.12/site-packages/sqlalchemy/engine/create.py", line 643, in connect
dash-app-1  |     return dialect.connect(*cargs, **cparams)
dash-app-1  |            ^^^^^^^^^^^^^^^^^^^^^^^^^^^^^^^^^^
dash-app-1  |   File "/usr/local/lib/python3.12/site-packages/sqlalchemy/engine/default.py", line 621, in connect
dash-app-1  |     return self.loaded_dbapi.connect(*cargs, **cparams)
dash-app-1  |            ^^^^^^^^^^^^^^^^^^^^^^^^^^^^^^^^^^^^^^^^^^^^
dash-app-1  |   File "/usr/local/lib/python3.12/site-packages/psycopg2/__init__.py", line 122, in connect
dash-app-1  |     conn = _connect(dsn, connection_factory=connection_factory, **kwasync)
dash-app-1  |            ^^^^^^^^^^^^^^^^^^^^^^^^^^^^^^^^^^^^^^^^^^^^^^^^^^^^^^^^^^^^^^^
dash-app-1  | psycopg2.OperationalError: connection to server at "postgres" (172.18.0.6), port 5432 failed: FATAL:  password authentication failed for user "None"
dash-app-1  | 
dash-app-1  | 
dash-app-1  | The above exception was the direct cause of the following exception:
dash-app-1  | 
dash-app-1  | Traceback (most recent call last):
dash-app-1  |   File "/usr/local/lib/python3.12/site-packages/flask/app.py", line 1473, in wsgi_app
dash-app-1  |     response = self.full_dispatch_request()
dash-app-1  |                ^^^^^^^^^^^^^^^^^^^^^^^^^^^^
dash-app-1  |   File "/usr/local/lib/python3.12/site-packages/flask/app.py", line 882, in full_dispatch_request
dash-app-1  |     rv = self.handle_user_exception(e)
dash-app-1  |          ^^^^^^^^^^^^^^^^^^^^^^^^^^^^^
dash-app-1  |   File "/usr/local/lib/python3.12/site-packages/flask/app.py", line 880, in full_dispatch_request
dash-app-1  |     rv = self.dispatch_request()
dash-app-1  |          ^^^^^^^^^^^^^^^^^^^^^^^
dash-app-1  |   File "/usr/local/lib/python3.12/site-packages/flask/app.py", line 865, in dispatch_request
dash-app-1  |     return self.ensure_sync(self.view_functions[rule.endpoint])(**view_args)  # type: ignore[no-any-return]
dash-app-1  |            ^^^^^^^^^^^^^^^^^^^^^^^^^^^^^^^^^^^^^^^^^^^^^^^^^^^^^^^^^^^^^^^^^
dash-app-1  |   File "/usr/local/lib/python3.12/site-packages/dash/dash.py", line 1414, in dispatch
dash-app-1  |     ctx.run(
dash-app-1  |   File "/usr/local/lib/python3.12/site-packages/dash/_callback.py", line 536, in add_context
dash-app-1  |     raise err
dash-app-1  |   File "/usr/local/lib/python3.12/site-packages/dash/_callback.py", line 525, in add_context
dash-app-1  |     output_value = _invoke_callback(func, *func_args, **func_kwargs)  # type: ignore[reportArgumentType]
dash-app-1  |                    ^^^^^^^^^^^^^^^^^^^^^^^^^^^^^^^^^^^^^^^^^^^^^^^^^
dash-app-1  |   File "/usr/local/lib/python3.12/site-packages/dash/_callback.py", line 47, in _invoke_callback
dash-app-1  |     return func(*args, **kwargs)  # %% callback invoked %%
dash-app-1  |            ^^^^^^^^^^^^^^^^^^^^^
dash-app-1  |   File "/app/apps/main_app.py", line 1587, in change_graph
dash-app-1  |     fig = activity_graph(language, user_type, time_type)
dash-app-1  |           ^^^^^^^^^^^^^^^^^^^^^^^^^^^^^^^^^^^^^^^^^^^^^^
dash-app-1  |   File "/app/apps/main_app.py", line 581, in activity_graph
dash-app-1  |     df = pd.read_sql_query(stmt, engine, params=params)
dash-app-1  |          ^^^^^^^^^^^^^^^^^^^^^^^^^^^^^^^^^^^^^^^^^^^^^^
dash-app-1  |   File "/usr/local/lib/python3.12/site-packages/pandas/io/sql.py", line 525, in read_sql_query
dash-app-1  |     with pandasSQL_builder(con) as pandas_sql:
dash-app-1  |          ^^^^^^^^^^^^^^^^^^^^^^
dash-app-1  |   File "/usr/local/lib/python3.12/site-packages/pandas/io/sql.py", line 906, in pandasSQL_builder
dash-app-1  |     return SQLDatabase(con, schema, need_transaction)
dash-app-1  |            ^^^^^^^^^^^^^^^^^^^^^^^^^^^^^^^^^^^^^^^^^^
dash-app-1  |   File "/usr/local/lib/python3.12/site-packages/pandas/io/sql.py", line 1636, in __init__
dash-app-1  |     con = self.exit_stack.enter_context(con.connect())
dash-app-1  |                                         ^^^^^^^^^^^^^
dash-app-1  |   File "/usr/local/lib/python3.12/site-packages/sqlalchemy/engine/base.py", line 3278, in connect
dash-app-1  |     return self._connection_cls(self)
dash-app-1  |            ^^^^^^^^^^^^^^^^^^^^^^^^^^
dash-app-1  |   File "/usr/local/lib/python3.12/site-packages/sqlalchemy/engine/base.py", line 148, in __init__
dash-app-1  |     Connection._handle_dbapi_exception_noconnection(
dash-app-1  |   File "/usr/local/lib/python3.12/site-packages/sqlalchemy/engine/base.py", line 2442, in _handle_dbapi_exception_noconnection
dash-app-1  |     raise sqlalchemy_exception.with_traceback(exc_info[2]) from e
dash-app-1  |   File "/usr/local/lib/python3.12/site-packages/sqlalchemy/engine/base.py", line 146, in __init__
dash-app-1  |     self._dbapi_connection = engine.raw_connection()
dash-app-1  |                              ^^^^^^^^^^^^^^^^^^^^^^^
dash-app-1  |   File "/usr/local/lib/python3.12/site-packages/sqlalchemy/engine/base.py", line 3302, in raw_connection
dash-app-1  |     return self.pool.connect()
dash-app-1  |            ^^^^^^^^^^^^^^^^^^^
dash-app-1  |   File "/usr/local/lib/python3.12/site-packages/sqlalchemy/pool/base.py", line 449, in connect
dash-app-1  |     return _ConnectionFairy._checkout(self)
dash-app-1  |            ^^^^^^^^^^^^^^^^^^^^^^^^^^^^^^^^
dash-app-1  |   File "/usr/local/lib/python3.12/site-packages/sqlalchemy/pool/base.py", line 1263, in _checkout
dash-app-1  |     fairy = _ConnectionRecord.checkout(pool)
dash-app-1  |             ^^^^^^^^^^^^^^^^^^^^^^^^^^^^^^^^
dash-app-1  |   File "/usr/local/lib/python3.12/site-packages/sqlalchemy/pool/base.py", line 712, in checkout
dash-app-1  |     rec = pool._do_get()
dash-app-1  |           ^^^^^^^^^^^^^^
dash-app-1  |   File "/usr/local/lib/python3.12/site-packages/sqlalchemy/pool/impl.py", line 179, in _do_get
dash-app-1  |     with util.safe_reraise():
dash-app-1  |          ^^^^^^^^^^^^^^^^^^^
dash-app-1  |   File "/usr/local/lib/python3.12/site-packages/sqlalchemy/util/langhelpers.py", line 146, in __exit__
dash-app-1  |     raise exc_value.with_traceback(exc_tb)
dash-app-1  |   File "/usr/local/lib/python3.12/site-packages/sqlalchemy/pool/impl.py", line 177, in _do_get
dash-app-1  |     return self._create_connection()
dash-app-1  |            ^^^^^^^^^^^^^^^^^^^^^^^^^
dash-app-1  |   File "/usr/local/lib/python3.12/site-packages/sqlalchemy/pool/base.py", line 390, in _create_connection
dash-app-1  |     return _ConnectionRecord(self)
dash-app-1  |            ^^^^^^^^^^^^^^^^^^^^^^^
dash-app-1  |   File "/usr/local/lib/python3.12/site-packages/sqlalchemy/pool/base.py", line 674, in __init__
dash-app-1  |     self.__connect()
dash-app-1  |   File "/usr/local/lib/python3.12/site-packages/sqlalchemy/pool/base.py", line 900, in __connect
dash-app-1  |     with util.safe_reraise():
dash-app-1  |          ^^^^^^^^^^^^^^^^^^^
dash-app-1  |   File "/usr/local/lib/python3.12/site-packages/sqlalchemy/util/langhelpers.py", line 146, in __exit__
dash-app-1  |     raise exc_value.with_traceback(exc_tb)
dash-app-1  |   File "/usr/local/lib/python3.12/site-packages/sqlalchemy/pool/base.py", line 896, in __connect
dash-app-1  |     self.dbapi_connection = connection = pool._invoke_creator(self)
dash-app-1  |                                          ^^^^^^^^^^^^^^^^^^^^^^^^^^
dash-app-1  |   File "/usr/local/lib/python3.12/site-packages/sqlalchemy/engine/create.py", line 643, in connect
dash-app-1  |     return dialect.connect(*cargs, **cparams)
dash-app-1  |            ^^^^^^^^^^^^^^^^^^^^^^^^^^^^^^^^^^
dash-app-1  |   File "/usr/local/lib/python3.12/site-packages/sqlalchemy/engine/default.py", line 621, in connect
dash-app-1  |     return self.loaded_dbapi.connect(*cargs, **cparams)
dash-app-1  |            ^^^^^^^^^^^^^^^^^^^^^^^^^^^^^^^^^^^^^^^^^^^^
dash-app-1  |   File "/usr/local/lib/python3.12/site-packages/psycopg2/__init__.py", line 122, in connect
dash-app-1  |     conn = _connect(dsn, connection_factory=connection_factory, **kwasync)
dash-app-1  |            ^^^^^^^^^^^^^^^^^^^^^^^^^^^^^^^^^^^^^^^^^^^^^^^^^^^^^^^^^^^^^^^
dash-app-1  | sqlalchemy.exc.OperationalError: (psycopg2.OperationalError) connection to server at "postgres" (172.18.0.6), port 5432 failed: FATAL:  password authentication failed for user "None"
dash-app-1  | 
dash-app-1  | (Background on this error at: https://sqlalche.me/e/20/e3q8)
dash-app-1  | 172.18.0.1 - - [01/Oct/2025 11:03:52] "POST /_dash-update-component HTTP/1.1" 500 -
dash-app-1  | 172.18.0.1 - - [01/Oct/2025 11:03:53] "POST /_dash-update-component HTTP/1.1" 200 -
dash-app-1  | [2025-10-01 11:03:53,757] ERROR in app: Exception on /_dash-update-component [POST]
dash-app-1  | Traceback (most recent call last):
dash-app-1  |   File "/usr/local/lib/python3.12/site-packages/flask/app.py", line 1473, in wsgi_app
dash-app-1  |     response = self.full_dispatch_request()
dash-app-1  |                ^^^^^^^^^^^^^^^^^^^^^^^^^^^^
dash-app-1  |   File "/usr/local/lib/python3.12/site-packages/flask/app.py", line 882, in full_dispatch_request
dash-app-1  |     rv = self.handle_user_exception(e)
dash-app-1  |          ^^^^^^^^^^^^^^^^^^^^^^^^^^^^^
dash-app-1  |   File "/usr/local/lib/python3.12/site-packages/flask/app.py", line 880, in full_dispatch_request
dash-app-1  |     rv = self.dispatch_request()
dash-app-1  |          ^^^^^^^^^^^^^^^^^^^^^^^
dash-app-1  |   File "/usr/local/lib/python3.12/site-packages/flask/app.py", line 865, in dispatch_request
dash-app-1  |     return self.ensure_sync(self.view_functions[rule.endpoint])(**view_args)  # type: ignore[no-any-return]
dash-app-1  |            ^^^^^^^^^^^^^^^^^^^^^^^^^^^^^^^^^^^^^^^^^^^^^^^^^^^^^^^^^^^^^^^^^
dash-app-1  |   File "/usr/local/lib/python3.12/site-packages/dash/dash.py", line 1414, in dispatch
dash-app-1  |     ctx.run(
dash-app-1  |   File "/usr/local/lib/python3.12/site-packages/dash/_callback.py", line 554, in add_context
dash-app-1  |     flat_output_values = flatten_grouping(output_value, output)
dash-app-1  |                          ^^^^^^^^^^^^^^^^^^^^^^^^^^^^^^^^^^^^^^
dash-app-1  |   File "/usr/local/lib/python3.12/site-packages/dash/_grouping.py", line 35, in flatten_grouping
dash-app-1  |     validate_grouping(grouping, schema)
dash-app-1  |   File "/usr/local/lib/python3.12/site-packages/dash/_grouping.py", line 210, in validate_grouping
dash-app-1  |     SchemaTypeValidationError.check(grouping, full_schema, path, (tuple, list))
dash-app-1  |   File "/usr/local/lib/python3.12/site-packages/dash/_grouping.py", line 162, in check
dash-app-1  |     raise SchemaTypeValidationError(value, full_schema, path, expected_type)
dash-app-1  | dash._grouping.SchemaTypeValidationError: Schema: [<Output `graph_container.children`>, <Output `retention_rate.disabled`>, <Output `admin.disabled`>, <Output `percentage_number.options`>, <Output `year_yearmonth.options`>, <Output `active_veryactive.options`>]
dash-app-1  | Path: ()
dash-app-1  | Expected type: (<class 'tuple'>, <class 'list'>)
dash-app-1  | Received value of type <class 'NoneType'>:
dash-app-1  |     None
dash-app-1  | 172.18.0.1 - - [01/Oct/2025 11:03:53] "POST /_dash-update-component HTTP/1.1" 500 -
dash-app-1  | 172.18.0.1 - - [01/Oct/2025 11:03:53] "GET /_dash-component-suites/dash/dcc/async-highlight.js HTTP/1.1" 304 -
dash-app-1  | 172.18.0.1 - - [01/Oct/2025 11:03:57] "POST /_dash-update-component HTTP/1.1" 200 -
dash-app-1  | [2025-10-01 11:03:57,078] ERROR in app: Exception on /_dash-update-component [POST]
dash-app-1  | Traceback (most recent call last):
dash-app-1  |   File "/usr/local/lib/python3.12/site-packages/flask/app.py", line 1473, in wsgi_app
dash-app-1  |     response = self.full_dispatch_request()
dash-app-1  |                ^^^^^^^^^^^^^^^^^^^^^^^^^^^^
dash-app-1  |   File "/usr/local/lib/python3.12/site-packages/flask/app.py", line 882, in full_dispatch_request
dash-app-1  |     rv = self.handle_user_exception(e)
dash-app-1  |          ^^^^^^^^^^^^^^^^^^^^^^^^^^^^^
dash-app-1  |   File "/usr/local/lib/python3.12/site-packages/flask/app.py", line 880, in full_dispatch_request
dash-app-1  |     rv = self.dispatch_request()
dash-app-1  |          ^^^^^^^^^^^^^^^^^^^^^^^
dash-app-1  |   File "/usr/local/lib/python3.12/site-packages/flask/app.py", line 865, in dispatch_request
dash-app-1  |     return self.ensure_sync(self.view_functions[rule.endpoint])(**view_args)  # type: ignore[no-any-return]
dash-app-1  |            ^^^^^^^^^^^^^^^^^^^^^^^^^^^^^^^^^^^^^^^^^^^^^^^^^^^^^^^^^^^^^^^^^
dash-app-1  |   File "/usr/local/lib/python3.12/site-packages/dash/dash.py", line 1414, in dispatch
dash-app-1  |     ctx.run(
dash-app-1  |   File "/usr/local/lib/python3.12/site-packages/dash/_callback.py", line 554, in add_context
dash-app-1  |     flat_output_values = flatten_grouping(output_value, output)
dash-app-1  |                          ^^^^^^^^^^^^^^^^^^^^^^^^^^^^^^^^^^^^^^
dash-app-1  |   File "/usr/local/lib/python3.12/site-packages/dash/_grouping.py", line 35, in flatten_grouping
dash-app-1  |     validate_grouping(grouping, schema)
dash-app-1  |   File "/usr/local/lib/python3.12/site-packages/dash/_grouping.py", line 210, in validate_grouping
dash-app-1  |     SchemaTypeValidationError.check(grouping, full_schema, path, (tuple, list))
dash-app-1  |   File "/usr/local/lib/python3.12/site-packages/dash/_grouping.py", line 162, in check
dash-app-1  |     raise SchemaTypeValidationError(value, full_schema, path, expected_type)
dash-app-1  | dash._grouping.SchemaTypeValidationError: Schema: [<Output `graph_container.children`>, <Output `retention_rate.disabled`>, <Output `admin.disabled`>, <Output `percentage_number.options`>, <Output `year_yearmonth.options`>, <Output `active_veryactive.options`>]
dash-app-1  | Path: ()
dash-app-1  | Expected type: (<class 'tuple'>, <class 'list'>)
dash-app-1  | Received value of type <class 'NoneType'>:
dash-app-1  |     None
dash-app-1  | 172.18.0.1 - - [01/Oct/2025 11:03:57] "POST /_dash-update-component HTTP/1.1" 500 -
dash-app-1  | 172.18.0.1 - - [01/Oct/2025 11:04:07] "POST /_dash-update-component HTTP/1.1" 200 -
dash-app-1  | [2025-10-01 11:04:07,480] ERROR in app: Exception on /_dash-update-component [POST]
dash-app-1  | Traceback (most recent call last):
dash-app-1  |   File "/usr/local/lib/python3.12/site-packages/flask/app.py", line 1473, in wsgi_app
dash-app-1  |     response = self.full_dispatch_request()
dash-app-1  |                ^^^^^^^^^^^^^^^^^^^^^^^^^^^^
dash-app-1  |   File "/usr/local/lib/python3.12/site-packages/flask/app.py", line 882, in full_dispatch_request
dash-app-1  |     rv = self.handle_user_exception(e)
dash-app-1  |          ^^^^^^^^^^^^^^^^^^^^^^^^^^^^^
dash-app-1  |   File "/usr/local/lib/python3.12/site-packages/flask/app.py", line 880, in full_dispatch_request
dash-app-1  |     rv = self.dispatch_request()
dash-app-1  |          ^^^^^^^^^^^^^^^^^^^^^^^
dash-app-1  |   File "/usr/local/lib/python3.12/site-packages/flask/app.py", line 865, in dispatch_request
dash-app-1  |     return self.ensure_sync(self.view_functions[rule.endpoint])(**view_args)  # type: ignore[no-any-return]
dash-app-1  |            ^^^^^^^^^^^^^^^^^^^^^^^^^^^^^^^^^^^^^^^^^^^^^^^^^^^^^^^^^^^^^^^^^
dash-app-1  |   File "/usr/local/lib/python3.12/site-packages/dash/dash.py", line 1414, in dispatch
dash-app-1  |     ctx.run(
dash-app-1  |   File "/usr/local/lib/python3.12/site-packages/dash/_callback.py", line 554, in add_context
dash-app-1  |     flat_output_values = flatten_grouping(output_value, output)
dash-app-1  |                          ^^^^^^^^^^^^^^^^^^^^^^^^^^^^^^^^^^^^^^
dash-app-1  |   File "/usr/local/lib/python3.12/site-packages/dash/_grouping.py", line 35, in flatten_grouping
dash-app-1  |     validate_grouping(grouping, schema)
dash-app-1  |   File "/usr/local/lib/python3.12/site-packages/dash/_grouping.py", line 210, in validate_grouping
dash-app-1  |     SchemaTypeValidationError.check(grouping, full_schema, path, (tuple, list))
dash-app-1  |   File "/usr/local/lib/python3.12/site-packages/dash/_grouping.py", line 162, in check
dash-app-1  |     raise SchemaTypeValidationError(value, full_schema, path, expected_type)
dash-app-1  | dash._grouping.SchemaTypeValidationError: Schema: [<Output `graph_container.children`>, <Output `retention_rate.disabled`>, <Output `admin.disabled`>, <Output `percentage_number.options`>, <Output `year_yearmonth.options`>, <Output `active_veryactive.options`>]
dash-app-1  | Path: ()
dash-app-1  | Expected type: (<class 'tuple'>, <class 'list'>)
dash-app-1  | Received value of type <class 'NoneType'>:
dash-app-1  |     None
dash-app-1  | 172.18.0.1 - - [01/Oct/2025 11:04:07] "POST /_dash-update-component HTTP/1.1" 500 -
dash-app-1  | 172.18.0.1 - - [01/Oct/2025 11:04:09] "POST /_dash-update-component HTTP/1.1" 200 -
dash-app-1  | [2025-10-01 11:04:09,286] ERROR in app: Exception on /_dash-update-component [POST]
dash-app-1  | Traceback (most recent call last):
dash-app-1  |   File "/usr/local/lib/python3.12/site-packages/flask/app.py", line 1473, in wsgi_app
dash-app-1  |     response = self.full_dispatch_request()
dash-app-1  |                ^^^^^^^^^^^^^^^^^^^^^^^^^^^^
dash-app-1  |   File "/usr/local/lib/python3.12/site-packages/flask/app.py", line 882, in full_dispatch_request
dash-app-1  |     rv = self.handle_user_exception(e)
dash-app-1  |          ^^^^^^^^^^^^^^^^^^^^^^^^^^^^^
dash-app-1  |   File "/usr/local/lib/python3.12/site-packages/flask/app.py", line 880, in full_dispatch_request
dash-app-1  |     rv = self.dispatch_request()
dash-app-1  |          ^^^^^^^^^^^^^^^^^^^^^^^
dash-app-1  |   File "/usr/local/lib/python3.12/site-packages/flask/app.py", line 865, in dispatch_request
dash-app-1  |     return self.ensure_sync(self.view_functions[rule.endpoint])(**view_args)  # type: ignore[no-any-return]
dash-app-1  |            ^^^^^^^^^^^^^^^^^^^^^^^^^^^^^^^^^^^^^^^^^^^^^^^^^^^^^^^^^^^^^^^^^
dash-app-1  |   File "/usr/local/lib/python3.12/site-packages/dash/dash.py", line 1414, in dispatch
dash-app-1  |     ctx.run(
dash-app-1  |   File "/usr/local/lib/python3.12/site-packages/dash/_callback.py", line 554, in add_context
dash-app-1  |     flat_output_values = flatten_grouping(output_value, output)
dash-app-1  |                          ^^^^^^^^^^^^^^^^^^^^^^^^^^^^^^^^^^^^^^
dash-app-1  |   File "/usr/local/lib/python3.12/site-packages/dash/_grouping.py", line 35, in flatten_grouping
dash-app-1  |     validate_grouping(grouping, schema)
dash-app-1  |   File "/usr/local/lib/python3.12/site-packages/dash/_grouping.py", line 210, in validate_grouping
dash-app-1  |     SchemaTypeValidationError.check(grouping, full_schema, path, (tuple, list))
dash-app-1  |   File "/usr/local/lib/python3.12/site-packages/dash/_grouping.py", line 162, in check
dash-app-1  |     raise SchemaTypeValidationError(value, full_schema, path, expected_type)
dash-app-1  | dash._grouping.SchemaTypeValidationError: Schema: [<Output `graph_container.children`>, <Output `retention_rate.disabled`>, <Output `admin.disabled`>, <Output `percentage_number.options`>, <Output `year_yearmonth.options`>, <Output `active_veryactive.options`>]
dash-app-1  | Path: ()
dash-app-1  | Expected type: (<class 'tuple'>, <class 'list'>)
dash-app-1  | Received value of type <class 'NoneType'>:
dash-app-1  |     None
dash-app-1  | 172.18.0.1 - - [01/Oct/2025 11:04:09] "POST /_dash-update-component HTTP/1.1" 500 -
dash-app-1  | 172.18.0.1 - - [01/Oct/2025 11:04:14] "GET /.well-known/appspecific/com.chrome.devtools.json HTTP/1.1" 200 -
dash-app-1  | 172.18.0.1 - - [01/Oct/2025 11:04:14] "GET /_dash-component-suites/dash/dcc/dash_core_components.js.map HTTP/1.1" 200 -
dash-app-1  | 172.18.0.1 - - [01/Oct/2025 11:04:14] "GET /_dash-component-suites/dash/dcc/dash_core_components-shared.js.map HTTP/1.1" 200 -
dash-app-1  | 172.18.0.1 - - [01/Oct/2025 11:04:14] "GET /_dash-component-suites/dash/dash_table/bundle.js.map HTTP/1.1" 200 -
dash-app-1  | 172.18.0.1 - - [01/Oct/2025 11:04:14] "GET /_dash-component-suites/dash/dcc/async-markdown.js.map HTTP/1.1" 200 -
dash-app-1  | 172.18.0.1 - - [01/Oct/2025 11:04:14] "GET /_dash-component-suites/dash/html/dash_html_components.min.js.map HTTP/1.1" 200 -
dash-app-1  | 172.18.0.1 - - [01/Oct/2025 11:04:18] "GET /_dash-component-suites/dash/dcc/async-dropdown.js.map HTTP/1.1" 200 -
dash-app-1  | 172.18.0.1 - - [01/Oct/2025 11:04:19] "GET /_dash-component-suites/dash/dcc/async-highlight.js.map HTTP/1.1" 200 -
dash-app-1  | 172.18.0.1 - - [01/Oct/2025 14:31:03] "GET / HTTP/1.1" 200 -
dash-app-1  | 172.18.0.1 - - [01/Oct/2025 14:31:04] "GET /_dash-dependencies HTTP/1.1" 200 -
dash-app-1  | 172.18.0.1 - - [01/Oct/2025 14:31:04] "GET /_dash-layout HTTP/1.1" 200 -
dash-app-1  | 172.18.0.1 - - [01/Oct/2025 14:31:04] "POST /_dash-update-component HTTP/1.1" 200 -
dash-app-1  | 172.18.0.1 - - [01/Oct/2025 14:31:04] "GET /assets/wikimedia-logo.png HTTP/1.1" 304 -
dash-app-1  | 172.18.0.1 - - [01/Oct/2025 14:31:04] "GET /assets/logo.png HTTP/1.1" 304 -
dash-app-1  | 172.18.0.1 - - [01/Oct/2025 14:31:06] "GET /main HTTP/1.1" 200 -
dash-app-1  | 172.18.0.1 - - [01/Oct/2025 14:31:06] "GET /_dash-layout HTTP/1.1" 200 -
dash-app-1  | 172.18.0.1 - - [01/Oct/2025 14:31:06] "GET /_dash-dependencies HTTP/1.1" 200 -
dash-app-1  | 172.18.0.1 - - [01/Oct/2025 14:31:07] "GET /assets/logo.png HTTP/1.1" 304 -
dash-app-1  | 172.18.0.1 - - [01/Oct/2025 14:31:07] "GET /assets/wikimedia-logo.png HTTP/1.1" 304 -
dash-app-1  | 172.18.0.1 - - [01/Oct/2025 14:31:07] "POST /_dash-update-component HTTP/1.1" 200 -
dash-app-1  | 172.18.0.1 - - [01/Oct/2025 14:31:08] "POST /_dash-update-component HTTP/1.1" 200 -
dash-app-1  | 172.18.0.1 - - [01/Oct/2025 14:31:08] "POST /_dash-update-component HTTP/1.1" 200 -
dash-app-1  | 172.18.0.1 - - [01/Oct/2025 14:31:08] "GET /_dash-component-suites/dash/dcc/async-markdown.js HTTP/1.1" 304 -
dash-app-1  | 172.18.0.1 - - [01/Oct/2025 14:31:08] "GET /_dash-component-suites/dash/dcc/async-dropdown.js HTTP/1.1" 304 -
dash-app-1  | [2025-10-01 14:31:08,503] ERROR in app: Exception on /_dash-update-component [POST]
dash-app-1  | Traceback (most recent call last):
dash-app-1  |   File "/usr/local/lib/python3.12/site-packages/sqlalchemy/engine/base.py", line 146, in __init__
dash-app-1  |     self._dbapi_connection = engine.raw_connection()
dash-app-1  |                              ^^^^^^^^^^^^^^^^^^^^^^^
dash-app-1  |   File "/usr/local/lib/python3.12/site-packages/sqlalchemy/engine/base.py", line 3302, in raw_connection
dash-app-1  |     return self.pool.connect()
dash-app-1  |            ^^^^^^^^^^^^^^^^^^^
dash-app-1  |   File "/usr/local/lib/python3.12/site-packages/sqlalchemy/pool/base.py", line 449, in connect
dash-app-1  |     return _ConnectionFairy._checkout(self)
dash-app-1  |            ^^^^^^^^^^^^^^^^^^^^^^^^^^^^^^^^
dash-app-1  |   File "/usr/local/lib/python3.12/site-packages/sqlalchemy/pool/base.py", line 1263, in _checkout
dash-app-1  |     fairy = _ConnectionRecord.checkout(pool)
dash-app-1  |             ^^^^^^^^^^^^^^^^^^^^^^^^^^^^^^^^
dash-app-1  |   File "/usr/local/lib/python3.12/site-packages/sqlalchemy/pool/base.py", line 712, in checkout
dash-app-1  |     rec = pool._do_get()
dash-app-1  |           ^^^^^^^^^^^^^^
dash-app-1  |   File "/usr/local/lib/python3.12/site-packages/sqlalchemy/pool/impl.py", line 179, in _do_get
dash-app-1  |     with util.safe_reraise():
dash-app-1  |          ^^^^^^^^^^^^^^^^^^^
dash-app-1  |   File "/usr/local/lib/python3.12/site-packages/sqlalchemy/util/langhelpers.py", line 146, in __exit__
dash-app-1  |     raise exc_value.with_traceback(exc_tb)
dash-app-1  |   File "/usr/local/lib/python3.12/site-packages/sqlalchemy/pool/impl.py", line 177, in _do_get
dash-app-1  |     return self._create_connection()
dash-app-1  |            ^^^^^^^^^^^^^^^^^^^^^^^^^
dash-app-1  |   File "/usr/local/lib/python3.12/site-packages/sqlalchemy/pool/base.py", line 390, in _create_connection
dash-app-1  |     return _ConnectionRecord(self)
dash-app-1  |            ^^^^^^^^^^^^^^^^^^^^^^^
dash-app-1  |   File "/usr/local/lib/python3.12/site-packages/sqlalchemy/pool/base.py", line 674, in __init__
dash-app-1  |     self.__connect()
dash-app-1  |   File "/usr/local/lib/python3.12/site-packages/sqlalchemy/pool/base.py", line 900, in __connect
dash-app-1  |     with util.safe_reraise():
dash-app-1  |          ^^^^^^^^^^^^^^^^^^^
dash-app-1  |   File "/usr/local/lib/python3.12/site-packages/sqlalchemy/util/langhelpers.py", line 146, in __exit__
dash-app-1  |     raise exc_value.with_traceback(exc_tb)
dash-app-1  |   File "/usr/local/lib/python3.12/site-packages/sqlalchemy/pool/base.py", line 896, in __connect
dash-app-1  |     self.dbapi_connection = connection = pool._invoke_creator(self)
dash-app-1  |                                          ^^^^^^^^^^^^^^^^^^^^^^^^^^
dash-app-1  |   File "/usr/local/lib/python3.12/site-packages/sqlalchemy/engine/create.py", line 643, in connect
dash-app-1  |     return dialect.connect(*cargs, **cparams)
dash-app-1  |            ^^^^^^^^^^^^^^^^^^^^^^^^^^^^^^^^^^
dash-app-1  |   File "/usr/local/lib/python3.12/site-packages/sqlalchemy/engine/default.py", line 621, in connect
dash-app-1  |     return self.loaded_dbapi.connect(*cargs, **cparams)
dash-app-1  |            ^^^^^^^^^^^^^^^^^^^^^^^^^^^^^^^^^^^^^^^^^^^^
dash-app-1  |   File "/usr/local/lib/python3.12/site-packages/psycopg2/__init__.py", line 122, in connect
dash-app-1  |     conn = _connect(dsn, connection_factory=connection_factory, **kwasync)
dash-app-1  |            ^^^^^^^^^^^^^^^^^^^^^^^^^^^^^^^^^^^^^^^^^^^^^^^^^^^^^^^^^^^^^^^
dash-app-1  | psycopg2.OperationalError: connection to server at "postgres" (172.18.0.6), port 5432 failed: FATAL:  password authentication failed for user "None"
dash-app-1  | 
dash-app-1  | 
dash-app-1  | The above exception was the direct cause of the following exception:
dash-app-1  | 
dash-app-1  | Traceback (most recent call last):
dash-app-1  |   File "/usr/local/lib/python3.12/site-packages/flask/app.py", line 1473, in wsgi_app
dash-app-1  |     response = self.full_dispatch_request()
dash-app-1  |                ^^^^^^^^^^^^^^^^^^^^^^^^^^^^
dash-app-1  |   File "/usr/local/lib/python3.12/site-packages/flask/app.py", line 882, in full_dispatch_request
dash-app-1  |     rv = self.handle_user_exception(e)
dash-app-1  |          ^^^^^^^^^^^^^^^^^^^^^^^^^^^^^
dash-app-1  |   File "/usr/local/lib/python3.12/site-packages/flask/app.py", line 880, in full_dispatch_request
dash-app-1  |     rv = self.dispatch_request()
dash-app-1  |          ^^^^^^^^^^^^^^^^^^^^^^^
dash-app-1  |   File "/usr/local/lib/python3.12/site-packages/flask/app.py", line 865, in dispatch_request
dash-app-1  |     return self.ensure_sync(self.view_functions[rule.endpoint])(**view_args)  # type: ignore[no-any-return]
dash-app-1  |            ^^^^^^^^^^^^^^^^^^^^^^^^^^^^^^^^^^^^^^^^^^^^^^^^^^^^^^^^^^^^^^^^^
dash-app-1  |   File "/usr/local/lib/python3.12/site-packages/dash/dash.py", line 1414, in dispatch
dash-app-1  |     ctx.run(
dash-app-1  |   File "/usr/local/lib/python3.12/site-packages/dash/_callback.py", line 536, in add_context
dash-app-1  |     raise err
dash-app-1  |   File "/usr/local/lib/python3.12/site-packages/dash/_callback.py", line 525, in add_context
dash-app-1  |     output_value = _invoke_callback(func, *func_args, **func_kwargs)  # type: ignore[reportArgumentType]
dash-app-1  |                    ^^^^^^^^^^^^^^^^^^^^^^^^^^^^^^^^^^^^^^^^^^^^^^^^^
dash-app-1  |   File "/usr/local/lib/python3.12/site-packages/dash/_callback.py", line 47, in _invoke_callback
dash-app-1  |     return func(*args, **kwargs)  # %% callback invoked %%
dash-app-1  |            ^^^^^^^^^^^^^^^^^^^^^
dash-app-1  |   File "/app/apps/main_app.py", line 1587, in change_graph
dash-app-1  |     fig = activity_graph(language, user_type, time_type)
dash-app-1  |           ^^^^^^^^^^^^^^^^^^^^^^^^^^^^^^^^^^^^^^^^^^^^^^
dash-app-1  |   File "/app/apps/main_app.py", line 581, in activity_graph
dash-app-1  |     df = pd.read_sql_query(stmt, engine, params=params)
dash-app-1  |          ^^^^^^^^^^^^^^^^^^^^^^^^^^^^^^^^^^^^^^^^^^^^^^
dash-app-1  |   File "/usr/local/lib/python3.12/site-packages/pandas/io/sql.py", line 525, in read_sql_query
dash-app-1  |     with pandasSQL_builder(con) as pandas_sql:
dash-app-1  |          ^^^^^^^^^^^^^^^^^^^^^^
dash-app-1  |   File "/usr/local/lib/python3.12/site-packages/pandas/io/sql.py", line 906, in pandasSQL_builder
dash-app-1  |     return SQLDatabase(con, schema, need_transaction)
dash-app-1  |            ^^^^^^^^^^^^^^^^^^^^^^^^^^^^^^^^^^^^^^^^^^
dash-app-1  |   File "/usr/local/lib/python3.12/site-packages/pandas/io/sql.py", line 1636, in __init__
dash-app-1  |     con = self.exit_stack.enter_context(con.connect())
dash-app-1  |                                         ^^^^^^^^^^^^^
dash-app-1  |   File "/usr/local/lib/python3.12/site-packages/sqlalchemy/engine/base.py", line 3278, in connect
dash-app-1  |     return self._connection_cls(self)
dash-app-1  |            ^^^^^^^^^^^^^^^^^^^^^^^^^^
dash-app-1  |   File "/usr/local/lib/python3.12/site-packages/sqlalchemy/engine/base.py", line 148, in __init__
dash-app-1  |     Connection._handle_dbapi_exception_noconnection(
dash-app-1  |   File "/usr/local/lib/python3.12/site-packages/sqlalchemy/engine/base.py", line 2442, in _handle_dbapi_exception_noconnection
dash-app-1  |     raise sqlalchemy_exception.with_traceback(exc_info[2]) from e
dash-app-1  |   File "/usr/local/lib/python3.12/site-packages/sqlalchemy/engine/base.py", line 146, in __init__
dash-app-1  |     self._dbapi_connection = engine.raw_connection()
dash-app-1  |                              ^^^^^^^^^^^^^^^^^^^^^^^
dash-app-1  |   File "/usr/local/lib/python3.12/site-packages/sqlalchemy/engine/base.py", line 3302, in raw_connection
dash-app-1  |     return self.pool.connect()
dash-app-1  |            ^^^^^^^^^^^^^^^^^^^
dash-app-1  |   File "/usr/local/lib/python3.12/site-packages/sqlalchemy/pool/base.py", line 449, in connect
dash-app-1  |     return _ConnectionFairy._checkout(self)
dash-app-1  |            ^^^^^^^^^^^^^^^^^^^^^^^^^^^^^^^^
dash-app-1  |   File "/usr/local/lib/python3.12/site-packages/sqlalchemy/pool/base.py", line 1263, in _checkout
dash-app-1  |     fairy = _ConnectionRecord.checkout(pool)
dash-app-1  |             ^^^^^^^^^^^^^^^^^^^^^^^^^^^^^^^^
dash-app-1  |   File "/usr/local/lib/python3.12/site-packages/sqlalchemy/pool/base.py", line 712, in checkout
dash-app-1  |     rec = pool._do_get()
dash-app-1  |           ^^^^^^^^^^^^^^
dash-app-1  |   File "/usr/local/lib/python3.12/site-packages/sqlalchemy/pool/impl.py", line 179, in _do_get
dash-app-1  |     with util.safe_reraise():
dash-app-1  |          ^^^^^^^^^^^^^^^^^^^
dash-app-1  |   File "/usr/local/lib/python3.12/site-packages/sqlalchemy/util/langhelpers.py", line 146, in __exit__
dash-app-1  |     raise exc_value.with_traceback(exc_tb)
dash-app-1  |   File "/usr/local/lib/python3.12/site-packages/sqlalchemy/pool/impl.py", line 177, in _do_get
dash-app-1  |     return self._create_connection()
dash-app-1  |            ^^^^^^^^^^^^^^^^^^^^^^^^^
dash-app-1  |   File "/usr/local/lib/python3.12/site-packages/sqlalchemy/pool/base.py", line 390, in _create_connection
dash-app-1  |     return _ConnectionRecord(self)
dash-app-1  |            ^^^^^^^^^^^^^^^^^^^^^^^
dash-app-1  |   File "/usr/local/lib/python3.12/site-packages/sqlalchemy/pool/base.py", line 674, in __init__
dash-app-1  |     self.__connect()
dash-app-1  |   File "/usr/local/lib/python3.12/site-packages/sqlalchemy/pool/base.py", line 900, in __connect
dash-app-1  |     with util.safe_reraise():
dash-app-1  |          ^^^^^^^^^^^^^^^^^^^
dash-app-1  |   File "/usr/local/lib/python3.12/site-packages/sqlalchemy/util/langhelpers.py", line 146, in __exit__
dash-app-1  |     raise exc_value.with_traceback(exc_tb)
dash-app-1  |   File "/usr/local/lib/python3.12/site-packages/sqlalchemy/pool/base.py", line 896, in __connect
dash-app-1  |     self.dbapi_connection = connection = pool._invoke_creator(self)
dash-app-1  |                                          ^^^^^^^^^^^^^^^^^^^^^^^^^^
dash-app-1  |   File "/usr/local/lib/python3.12/site-packages/sqlalchemy/engine/create.py", line 643, in connect
dash-app-1  |     return dialect.connect(*cargs, **cparams)
dash-app-1  |            ^^^^^^^^^^^^^^^^^^^^^^^^^^^^^^^^^^
dash-app-1  |   File "/usr/local/lib/python3.12/site-packages/sqlalchemy/engine/default.py", line 621, in connect
dash-app-1  |     return self.loaded_dbapi.connect(*cargs, **cparams)
dash-app-1  |            ^^^^^^^^^^^^^^^^^^^^^^^^^^^^^^^^^^^^^^^^^^^^
dash-app-1  |   File "/usr/local/lib/python3.12/site-packages/psycopg2/__init__.py", line 122, in connect
dash-app-1  |     conn = _connect(dsn, connection_factory=connection_factory, **kwasync)
dash-app-1  |            ^^^^^^^^^^^^^^^^^^^^^^^^^^^^^^^^^^^^^^^^^^^^^^^^^^^^^^^^^^^^^^^
dash-app-1  | sqlalchemy.exc.OperationalError: (psycopg2.OperationalError) connection to server at "postgres" (172.18.0.6), port 5432 failed: FATAL:  password authentication failed for user "None"
dash-app-1  | 
dash-app-1  | (Background on this error at: https://sqlalche.me/e/20/e3q8)
dash-app-1  | 172.18.0.1 - - [01/Oct/2025 14:31:08] "POST /_dash-update-component HTTP/1.1" 500 -
dash-app-1  | 172.18.0.1 - - [01/Oct/2025 14:31:09] "POST /_dash-update-component HTTP/1.1" 200 -
dash-app-1  | [2025-10-01 14:31:09,141] ERROR in app: Exception on /_dash-update-component [POST]
dash-app-1  | Traceback (most recent call last):
dash-app-1  |   File "/usr/local/lib/python3.12/site-packages/flask/app.py", line 1473, in wsgi_app
dash-app-1  |     response = self.full_dispatch_request()
dash-app-1  |                ^^^^^^^^^^^^^^^^^^^^^^^^^^^^
dash-app-1  |   File "/usr/local/lib/python3.12/site-packages/flask/app.py", line 882, in full_dispatch_request
dash-app-1  |     rv = self.handle_user_exception(e)
dash-app-1  |          ^^^^^^^^^^^^^^^^^^^^^^^^^^^^^
dash-app-1  |   File "/usr/local/lib/python3.12/site-packages/flask/app.py", line 880, in full_dispatch_request
dash-app-1  |     rv = self.dispatch_request()
dash-app-1  |          ^^^^^^^^^^^^^^^^^^^^^^^
dash-app-1  |   File "/usr/local/lib/python3.12/site-packages/flask/app.py", line 865, in dispatch_request
dash-app-1  |     return self.ensure_sync(self.view_functions[rule.endpoint])(**view_args)  # type: ignore[no-any-return]
dash-app-1  |            ^^^^^^^^^^^^^^^^^^^^^^^^^^^^^^^^^^^^^^^^^^^^^^^^^^^^^^^^^^^^^^^^^
dash-app-1  |   File "/usr/local/lib/python3.12/site-packages/dash/dash.py", line 1414, in dispatch
dash-app-1  |     ctx.run(
dash-app-1  |   File "/usr/local/lib/python3.12/site-packages/dash/_callback.py", line 554, in add_context
dash-app-1  |     flat_output_values = flatten_grouping(output_value, output)
dash-app-1  |                          ^^^^^^^^^^^^^^^^^^^^^^^^^^^^^^^^^^^^^^
dash-app-1  |   File "/usr/local/lib/python3.12/site-packages/dash/_grouping.py", line 35, in flatten_grouping
dash-app-1  |     validate_grouping(grouping, schema)
dash-app-1  |   File "/usr/local/lib/python3.12/site-packages/dash/_grouping.py", line 210, in validate_grouping
dash-app-1  |     SchemaTypeValidationError.check(grouping, full_schema, path, (tuple, list))
dash-app-1  |   File "/usr/local/lib/python3.12/site-packages/dash/_grouping.py", line 162, in check
dash-app-1  |     raise SchemaTypeValidationError(value, full_schema, path, expected_type)
dash-app-1  | dash._grouping.SchemaTypeValidationError: Schema: [<Output `graph_container.children`>, <Output `retention_rate.disabled`>, <Output `admin.disabled`>, <Output `percentage_number.options`>, <Output `year_yearmonth.options`>, <Output `active_veryactive.options`>]
dash-app-1  | Path: ()
dash-app-1  | Expected type: (<class 'tuple'>, <class 'list'>)
dash-app-1  | Received value of type <class 'NoneType'>:
dash-app-1  |     None
dash-app-1  | 172.18.0.1 - - [01/Oct/2025 14:31:09] "GET /_dash-component-suites/dash/dcc/async-highlight.js HTTP/1.1" 304 -
dash-app-1  | 172.18.0.1 - - [01/Oct/2025 14:31:09] "POST /_dash-update-component HTTP/1.1" 500 -
dash-app-1  | 172.18.0.1 - - [01/Oct/2025 14:31:17] "GET /.well-known/appspecific/com.chrome.devtools.json HTTP/1.1" 200 -
dash-app-1  | 172.18.0.1 - - [01/Oct/2025 14:31:17] "GET /_dash-component-suites/dash/dcc/dash_core_components-shared.js.map HTTP/1.1" 304 -
dash-app-1  | 172.18.0.1 - - [01/Oct/2025 14:31:17] "GET /_dash-component-suites/dash/dash_table/bundle.js.map HTTP/1.1" 304 -
dash-app-1  | 172.18.0.1 - - [01/Oct/2025 14:31:17] "GET /_dash-component-suites/dash/dcc/async-dropdown.js.map HTTP/1.1" 304 -
dash-app-1  | 172.18.0.1 - - [01/Oct/2025 14:31:17] "GET /_dash-component-suites/dash/html/dash_html_components.min.js.map HTTP/1.1" 304 -
dash-app-1  | 172.18.0.1 - - [01/Oct/2025 14:31:17] "GET /_dash-component-suites/dash/dcc/dash_core_components.js.map HTTP/1.1" 304 -
dash-app-1  | 172.18.0.1 - - [01/Oct/2025 14:31:17] "GET /_dash-component-suites/dash/dcc/async-markdown.js.map HTTP/1.1" 304 -
dash-app-1  | 172.18.0.1 - - [01/Oct/2025 14:31:17] "GET /_dash-component-suites/dash/dcc/async-highlight.js.map HTTP/1.1" 304 -
dash-app-1  | 172.18.0.1 - - [01/Oct/2025 14:31:22] "GET /_dash-update-component HTTP/1.1" 200 -
dash-app-1  | 172.18.0.1 - - [01/Oct/2025 14:31:22] "GET /_dash-layout HTTP/1.1" 200 -
dash-app-1  | 172.18.0.1 - - [01/Oct/2025 14:31:22] "GET /_dash-dependencies HTTP/1.1" 200 -
dash-app-1  | 172.18.0.1 - - [01/Oct/2025 14:31:23] "POST /_dash-update-component HTTP/1.1" 200 -
dash-app-1  | 172.18.0.1 - - [01/Oct/2025 14:31:23] "GET /assets/logo.png HTTP/1.1" 304 -
dash-app-1  | 172.18.0.1 - - [01/Oct/2025 14:31:23] "GET /assets/wikimedia-logo.png HTTP/1.1" 304 -
dash-app-1  | 172.18.0.1 - - [01/Oct/2025 14:31:26] "GET /main HTTP/1.1" 200 -
dash-app-1  | 172.18.0.1 - - [01/Oct/2025 14:31:26] "GET /_dash-layout HTTP/1.1" 200 -
dash-app-1  | 172.18.0.1 - - [01/Oct/2025 14:31:26] "GET /_dash-dependencies HTTP/1.1" 200 -
dash-app-1  | 172.18.0.1 - - [01/Oct/2025 14:31:27] "GET /assets/logo.png HTTP/1.1" 304 -
dash-app-1  | 172.18.0.1 - - [01/Oct/2025 14:31:27] "POST /_dash-update-component HTTP/1.1" 200 -
dash-app-1  | 172.18.0.1 - - [01/Oct/2025 14:31:27] "GET /assets/wikimedia-logo.png HTTP/1.1" 304 -
dash-app-1  | 172.18.0.1 - - [01/Oct/2025 14:31:28] "POST /_dash-update-component HTTP/1.1" 200 -
dash-app-1  | 172.18.0.1 - - [01/Oct/2025 14:31:28] "POST /_dash-update-component HTTP/1.1" 200 -
dash-app-1  | 172.18.0.1 - - [01/Oct/2025 14:31:28] "GET /_dash-component-suites/dash/dcc/async-dropdown.js HTTP/1.1" 304 -
dash-app-1  | 172.18.0.1 - - [01/Oct/2025 14:31:28] "GET /_dash-component-suites/dash/dcc/async-markdown.js HTTP/1.1" 304 -
dash-app-1  | [2025-10-01 14:31:28,469] ERROR in app: Exception on /_dash-update-component [POST]
dash-app-1  | Traceback (most recent call last):
dash-app-1  |   File "/usr/local/lib/python3.12/site-packages/sqlalchemy/engine/base.py", line 146, in __init__
dash-app-1  |     self._dbapi_connection = engine.raw_connection()
dash-app-1  |                              ^^^^^^^^^^^^^^^^^^^^^^^
dash-app-1  |   File "/usr/local/lib/python3.12/site-packages/sqlalchemy/engine/base.py", line 3302, in raw_connection
dash-app-1  |     return self.pool.connect()
dash-app-1  |            ^^^^^^^^^^^^^^^^^^^
dash-app-1  |   File "/usr/local/lib/python3.12/site-packages/sqlalchemy/pool/base.py", line 449, in connect
dash-app-1  |     return _ConnectionFairy._checkout(self)
dash-app-1  |            ^^^^^^^^^^^^^^^^^^^^^^^^^^^^^^^^
dash-app-1  |   File "/usr/local/lib/python3.12/site-packages/sqlalchemy/pool/base.py", line 1263, in _checkout
dash-app-1  |     fairy = _ConnectionRecord.checkout(pool)
dash-app-1  |             ^^^^^^^^^^^^^^^^^^^^^^^^^^^^^^^^
dash-app-1  |   File "/usr/local/lib/python3.12/site-packages/sqlalchemy/pool/base.py", line 712, in checkout
dash-app-1  |     rec = pool._do_get()
dash-app-1  |           ^^^^^^^^^^^^^^
dash-app-1  |   File "/usr/local/lib/python3.12/site-packages/sqlalchemy/pool/impl.py", line 179, in _do_get
dash-app-1  |     with util.safe_reraise():
dash-app-1  |          ^^^^^^^^^^^^^^^^^^^
dash-app-1  |   File "/usr/local/lib/python3.12/site-packages/sqlalchemy/util/langhelpers.py", line 146, in __exit__
dash-app-1  |     raise exc_value.with_traceback(exc_tb)
dash-app-1  |   File "/usr/local/lib/python3.12/site-packages/sqlalchemy/pool/impl.py", line 177, in _do_get
dash-app-1  |     return self._create_connection()
dash-app-1  |            ^^^^^^^^^^^^^^^^^^^^^^^^^
dash-app-1  |   File "/usr/local/lib/python3.12/site-packages/sqlalchemy/pool/base.py", line 390, in _create_connection
dash-app-1  |     return _ConnectionRecord(self)
dash-app-1  |            ^^^^^^^^^^^^^^^^^^^^^^^
dash-app-1  |   File "/usr/local/lib/python3.12/site-packages/sqlalchemy/pool/base.py", line 674, in __init__
dash-app-1  |     self.__connect()
dash-app-1  |   File "/usr/local/lib/python3.12/site-packages/sqlalchemy/pool/base.py", line 900, in __connect
dash-app-1  |     with util.safe_reraise():
dash-app-1  |          ^^^^^^^^^^^^^^^^^^^
dash-app-1  |   File "/usr/local/lib/python3.12/site-packages/sqlalchemy/util/langhelpers.py", line 146, in __exit__
dash-app-1  |     raise exc_value.with_traceback(exc_tb)
dash-app-1  |   File "/usr/local/lib/python3.12/site-packages/sqlalchemy/pool/base.py", line 896, in __connect
dash-app-1  |     self.dbapi_connection = connection = pool._invoke_creator(self)
dash-app-1  |                                          ^^^^^^^^^^^^^^^^^^^^^^^^^^
dash-app-1  |   File "/usr/local/lib/python3.12/site-packages/sqlalchemy/engine/create.py", line 643, in connect
dash-app-1  |     return dialect.connect(*cargs, **cparams)
dash-app-1  |            ^^^^^^^^^^^^^^^^^^^^^^^^^^^^^^^^^^
dash-app-1  |   File "/usr/local/lib/python3.12/site-packages/sqlalchemy/engine/default.py", line 621, in connect
dash-app-1  |     return self.loaded_dbapi.connect(*cargs, **cparams)
dash-app-1  |            ^^^^^^^^^^^^^^^^^^^^^^^^^^^^^^^^^^^^^^^^^^^^
dash-app-1  |   File "/usr/local/lib/python3.12/site-packages/psycopg2/__init__.py", line 122, in connect
dash-app-1  |     conn = _connect(dsn, connection_factory=connection_factory, **kwasync)
dash-app-1  |            ^^^^^^^^^^^^^^^^^^^^^^^^^^^^^^^^^^^^^^^^^^^^^^^^^^^^^^^^^^^^^^^
dash-app-1  | psycopg2.OperationalError: connection to server at "postgres" (172.18.0.6), port 5432 failed: FATAL:  password authentication failed for user "None"
dash-app-1  | 
dash-app-1  | 
dash-app-1  | The above exception was the direct cause of the following exception:
dash-app-1  | 
dash-app-1  | Traceback (most recent call last):
dash-app-1  |   File "/usr/local/lib/python3.12/site-packages/flask/app.py", line 1473, in wsgi_app
dash-app-1  |     response = self.full_dispatch_request()
dash-app-1  |                ^^^^^^^^^^^^^^^^^^^^^^^^^^^^
dash-app-1  |   File "/usr/local/lib/python3.12/site-packages/flask/app.py", line 882, in full_dispatch_request
dash-app-1  |     rv = self.handle_user_exception(e)
dash-app-1  |          ^^^^^^^^^^^^^^^^^^^^^^^^^^^^^
dash-app-1  |   File "/usr/local/lib/python3.12/site-packages/flask/app.py", line 880, in full_dispatch_request
dash-app-1  |     rv = self.dispatch_request()
dash-app-1  |          ^^^^^^^^^^^^^^^^^^^^^^^
dash-app-1  |   File "/usr/local/lib/python3.12/site-packages/flask/app.py", line 865, in dispatch_request
dash-app-1  |     return self.ensure_sync(self.view_functions[rule.endpoint])(**view_args)  # type: ignore[no-any-return]
dash-app-1  |            ^^^^^^^^^^^^^^^^^^^^^^^^^^^^^^^^^^^^^^^^^^^^^^^^^^^^^^^^^^^^^^^^^
dash-app-1  |   File "/usr/local/lib/python3.12/site-packages/dash/dash.py", line 1414, in dispatch
dash-app-1  |     ctx.run(
dash-app-1  |   File "/usr/local/lib/python3.12/site-packages/dash/_callback.py", line 536, in add_context
dash-app-1  |     raise err
dash-app-1  |   File "/usr/local/lib/python3.12/site-packages/dash/_callback.py", line 525, in add_context
dash-app-1  |     output_value = _invoke_callback(func, *func_args, **func_kwargs)  # type: ignore[reportArgumentType]
dash-app-1  |                    ^^^^^^^^^^^^^^^^^^^^^^^^^^^^^^^^^^^^^^^^^^^^^^^^^
dash-app-1  |   File "/usr/local/lib/python3.12/site-packages/dash/_callback.py", line 47, in _invoke_callback
dash-app-1  |     return func(*args, **kwargs)  # %% callback invoked %%
dash-app-1  |            ^^^^^^^^^^^^^^^^^^^^^
dash-app-1  |   File "/app/apps/main_app.py", line 1587, in change_graph
dash-app-1  |     fig = activity_graph(language, user_type, time_type)
dash-app-1  |           ^^^^^^^^^^^^^^^^^^^^^^^^^^^^^^^^^^^^^^^^^^^^^^
dash-app-1  |   File "/app/apps/main_app.py", line 581, in activity_graph
dash-app-1  |     df = pd.read_sql_query(stmt, engine, params=params)
dash-app-1  |          ^^^^^^^^^^^^^^^^^^^^^^^^^^^^^^^^^^^^^^^^^^^^^^
dash-app-1  |   File "/usr/local/lib/python3.12/site-packages/pandas/io/sql.py", line 525, in read_sql_query
dash-app-1  |     with pandasSQL_builder(con) as pandas_sql:
dash-app-1  |          ^^^^^^^^^^^^^^^^^^^^^^
dash-app-1  |   File "/usr/local/lib/python3.12/site-packages/pandas/io/sql.py", line 906, in pandasSQL_builder
dash-app-1  |     return SQLDatabase(con, schema, need_transaction)
dash-app-1  |            ^^^^^^^^^^^^^^^^^^^^^^^^^^^^^^^^^^^^^^^^^^
dash-app-1  |   File "/usr/local/lib/python3.12/site-packages/pandas/io/sql.py", line 1636, in __init__
dash-app-1  |     con = self.exit_stack.enter_context(con.connect())
dash-app-1  |                                         ^^^^^^^^^^^^^
dash-app-1  |   File "/usr/local/lib/python3.12/site-packages/sqlalchemy/engine/base.py", line 3278, in connect
dash-app-1  |     return self._connection_cls(self)
dash-app-1  |            ^^^^^^^^^^^^^^^^^^^^^^^^^^
dash-app-1  |   File "/usr/local/lib/python3.12/site-packages/sqlalchemy/engine/base.py", line 148, in __init__
dash-app-1  |     Connection._handle_dbapi_exception_noconnection(
dash-app-1  |   File "/usr/local/lib/python3.12/site-packages/sqlalchemy/engine/base.py", line 2442, in _handle_dbapi_exception_noconnection
dash-app-1  |     raise sqlalchemy_exception.with_traceback(exc_info[2]) from e
dash-app-1  |   File "/usr/local/lib/python3.12/site-packages/sqlalchemy/engine/base.py", line 146, in __init__
dash-app-1  |     self._dbapi_connection = engine.raw_connection()
dash-app-1  |                              ^^^^^^^^^^^^^^^^^^^^^^^
dash-app-1  |   File "/usr/local/lib/python3.12/site-packages/sqlalchemy/engine/base.py", line 3302, in raw_connection
dash-app-1  |     return self.pool.connect()
dash-app-1  |            ^^^^^^^^^^^^^^^^^^^
dash-app-1  |   File "/usr/local/lib/python3.12/site-packages/sqlalchemy/pool/base.py", line 449, in connect
dash-app-1  |     return _ConnectionFairy._checkout(self)
dash-app-1  |            ^^^^^^^^^^^^^^^^^^^^^^^^^^^^^^^^
dash-app-1  |   File "/usr/local/lib/python3.12/site-packages/sqlalchemy/pool/base.py", line 1263, in _checkout
dash-app-1  |     fairy = _ConnectionRecord.checkout(pool)
dash-app-1  |             ^^^^^^^^^^^^^^^^^^^^^^^^^^^^^^^^
dash-app-1  |   File "/usr/local/lib/python3.12/site-packages/sqlalchemy/pool/base.py", line 712, in checkout
dash-app-1  |     rec = pool._do_get()
dash-app-1  |           ^^^^^^^^^^^^^^
dash-app-1  |   File "/usr/local/lib/python3.12/site-packages/sqlalchemy/pool/impl.py", line 179, in _do_get
dash-app-1  |     with util.safe_reraise():
dash-app-1  |          ^^^^^^^^^^^^^^^^^^^
dash-app-1  |   File "/usr/local/lib/python3.12/site-packages/sqlalchemy/util/langhelpers.py", line 146, in __exit__
dash-app-1  |     raise exc_value.with_traceback(exc_tb)
dash-app-1  |   File "/usr/local/lib/python3.12/site-packages/sqlalchemy/pool/impl.py", line 177, in _do_get
dash-app-1  |     return self._create_connection()
dash-app-1  |            ^^^^^^^^^^^^^^^^^^^^^^^^^
dash-app-1  |   File "/usr/local/lib/python3.12/site-packages/sqlalchemy/pool/base.py", line 390, in _create_connection
dash-app-1  |     return _ConnectionRecord(self)
dash-app-1  |            ^^^^^^^^^^^^^^^^^^^^^^^
dash-app-1  |   File "/usr/local/lib/python3.12/site-packages/sqlalchemy/pool/base.py", line 674, in __init__
dash-app-1  |     self.__connect()
dash-app-1  |   File "/usr/local/lib/python3.12/site-packages/sqlalchemy/pool/base.py", line 900, in __connect
dash-app-1  |     with util.safe_reraise():
dash-app-1  |          ^^^^^^^^^^^^^^^^^^^
dash-app-1  |   File "/usr/local/lib/python3.12/site-packages/sqlalchemy/util/langhelpers.py", line 146, in __exit__
dash-app-1  |     raise exc_value.with_traceback(exc_tb)
dash-app-1  |   File "/usr/local/lib/python3.12/site-packages/sqlalchemy/pool/base.py", line 896, in __connect
dash-app-1  |     self.dbapi_connection = connection = pool._invoke_creator(self)
dash-app-1  |                                          ^^^^^^^^^^^^^^^^^^^^^^^^^^
dash-app-1  |   File "/usr/local/lib/python3.12/site-packages/sqlalchemy/engine/create.py", line 643, in connect
dash-app-1  |     return dialect.connect(*cargs, **cparams)
dash-app-1  |            ^^^^^^^^^^^^^^^^^^^^^^^^^^^^^^^^^^
dash-app-1  |   File "/usr/local/lib/python3.12/site-packages/sqlalchemy/engine/default.py", line 621, in connect
dash-app-1  |     return self.loaded_dbapi.connect(*cargs, **cparams)
dash-app-1  |            ^^^^^^^^^^^^^^^^^^^^^^^^^^^^^^^^^^^^^^^^^^^^
dash-app-1  |   File "/usr/local/lib/python3.12/site-packages/psycopg2/__init__.py", line 122, in connect
dash-app-1  |     conn = _connect(dsn, connection_factory=connection_factory, **kwasync)
dash-app-1  |            ^^^^^^^^^^^^^^^^^^^^^^^^^^^^^^^^^^^^^^^^^^^^^^^^^^^^^^^^^^^^^^^
dash-app-1  | sqlalchemy.exc.OperationalError: (psycopg2.OperationalError) connection to server at "postgres" (172.18.0.6), port 5432 failed: FATAL:  password authentication failed for user "None"
dash-app-1  | 
dash-app-1  | (Background on this error at: https://sqlalche.me/e/20/e3q8)
dash-app-1  | 172.18.0.1 - - [01/Oct/2025 14:31:28] "POST /_dash-update-component HTTP/1.1" 500 -
dash-app-1  | 172.18.0.1 - - [01/Oct/2025 14:31:28] "POST /_dash-update-component HTTP/1.1" 200 -
dash-app-1  | [2025-10-01 14:31:28,852] ERROR in app: Exception on /_dash-update-component [POST]
dash-app-1  | Traceback (most recent call last):
dash-app-1  |   File "/usr/local/lib/python3.12/site-packages/flask/app.py", line 1473, in wsgi_app
dash-app-1  |     response = self.full_dispatch_request()
dash-app-1  |                ^^^^^^^^^^^^^^^^^^^^^^^^^^^^
dash-app-1  |   File "/usr/local/lib/python3.12/site-packages/flask/app.py", line 882, in full_dispatch_request
dash-app-1  |     rv = self.handle_user_exception(e)
dash-app-1  |          ^^^^^^^^^^^^^^^^^^^^^^^^^^^^^
dash-app-1  |   File "/usr/local/lib/python3.12/site-packages/flask/app.py", line 880, in full_dispatch_request
dash-app-1  |     rv = self.dispatch_request()
dash-app-1  |          ^^^^^^^^^^^^^^^^^^^^^^^
dash-app-1  |   File "/usr/local/lib/python3.12/site-packages/flask/app.py", line 865, in dispatch_request
dash-app-1  |     return self.ensure_sync(self.view_functions[rule.endpoint])(**view_args)  # type: ignore[no-any-return]
dash-app-1  |            ^^^^^^^^^^^^^^^^^^^^^^^^^^^^^^^^^^^^^^^^^^^^^^^^^^^^^^^^^^^^^^^^^
dash-app-1  |   File "/usr/local/lib/python3.12/site-packages/dash/dash.py", line 1414, in dispatch
dash-app-1  |     ctx.run(
dash-app-1  |   File "/usr/local/lib/python3.12/site-packages/dash/_callback.py", line 554, in add_context
dash-app-1  |     flat_output_values = flatten_grouping(output_value, output)
dash-app-1  |                          ^^^^^^^^^^^^^^^^^^^^^^^^^^^^^^^^^^^^^^
dash-app-1  |   File "/usr/local/lib/python3.12/site-packages/dash/_grouping.py", line 35, in flatten_grouping
dash-app-1  |     validate_grouping(grouping, schema)
dash-app-1  |   File "/usr/local/lib/python3.12/site-packages/dash/_grouping.py", line 210, in validate_grouping
dash-app-1  |     SchemaTypeValidationError.check(grouping, full_schema, path, (tuple, list))
dash-app-1  |   File "/usr/local/lib/python3.12/site-packages/dash/_grouping.py", line 162, in check
dash-app-1  |     raise SchemaTypeValidationError(value, full_schema, path, expected_type)
dash-app-1  | dash._grouping.SchemaTypeValidationError: Schema: [<Output `graph_container.children`>, <Output `retention_rate.disabled`>, <Output `admin.disabled`>, <Output `percentage_number.options`>, <Output `year_yearmonth.options`>, <Output `active_veryactive.options`>]
dash-app-1  | Path: ()
dash-app-1  | Expected type: (<class 'tuple'>, <class 'list'>)
dash-app-1  | Received value of type <class 'NoneType'>:
dash-app-1  |     None
dash-app-1  | 172.18.0.1 - - [01/Oct/2025 14:31:28] "POST /_dash-update-component HTTP/1.1" 500 -
dash-app-1  | 172.18.0.1 - - [01/Oct/2025 14:31:28] "GET /_dash-component-suites/dash/dcc/async-highlight.js HTTP/1.1" 304 -
dash-app-1  | 172.18.0.1 - - [01/Oct/2025 14:31:33] "POST /_dash-update-component HTTP/1.1" 200 -
dash-app-1  | [2025-10-01 14:31:33,454] ERROR in app: Exception on /_dash-update-component [POST]
dash-app-1  | Traceback (most recent call last):
dash-app-1  |   File "/usr/local/lib/python3.12/site-packages/flask/app.py", line 1473, in wsgi_app
dash-app-1  |     response = self.full_dispatch_request()
dash-app-1  |                ^^^^^^^^^^^^^^^^^^^^^^^^^^^^
dash-app-1  |   File "/usr/local/lib/python3.12/site-packages/flask/app.py", line 882, in full_dispatch_request
dash-app-1  |     rv = self.handle_user_exception(e)
dash-app-1  |          ^^^^^^^^^^^^^^^^^^^^^^^^^^^^^
dash-app-1  |   File "/usr/local/lib/python3.12/site-packages/flask/app.py", line 880, in full_dispatch_request
dash-app-1  |     rv = self.dispatch_request()
dash-app-1  |          ^^^^^^^^^^^^^^^^^^^^^^^
dash-app-1  |   File "/usr/local/lib/python3.12/site-packages/flask/app.py", line 865, in dispatch_request
dash-app-1  |     return self.ensure_sync(self.view_functions[rule.endpoint])(**view_args)  # type: ignore[no-any-return]
dash-app-1  |            ^^^^^^^^^^^^^^^^^^^^^^^^^^^^^^^^^^^^^^^^^^^^^^^^^^^^^^^^^^^^^^^^^
dash-app-1  |   File "/usr/local/lib/python3.12/site-packages/dash/dash.py", line 1414, in dispatch
dash-app-1  |     ctx.run(
dash-app-1  |   File "/usr/local/lib/python3.12/site-packages/dash/_callback.py", line 554, in add_context
dash-app-1  |     flat_output_values = flatten_grouping(output_value, output)
dash-app-1  |                          ^^^^^^^^^^^^^^^^^^^^^^^^^^^^^^^^^^^^^^
dash-app-1  |   File "/usr/local/lib/python3.12/site-packages/dash/_grouping.py", line 35, in flatten_grouping
dash-app-1  |     validate_grouping(grouping, schema)
dash-app-1  |   File "/usr/local/lib/python3.12/site-packages/dash/_grouping.py", line 210, in validate_grouping
dash-app-1  |     SchemaTypeValidationError.check(grouping, full_schema, path, (tuple, list))
dash-app-1  |   File "/usr/local/lib/python3.12/site-packages/dash/_grouping.py", line 162, in check
dash-app-1  |     raise SchemaTypeValidationError(value, full_schema, path, expected_type)
dash-app-1  | dash._grouping.SchemaTypeValidationError: Schema: [<Output `graph_container.children`>, <Output `retention_rate.disabled`>, <Output `admin.disabled`>, <Output `percentage_number.options`>, <Output `year_yearmonth.options`>, <Output `active_veryactive.options`>]
dash-app-1  | Path: ()
dash-app-1  | Expected type: (<class 'tuple'>, <class 'list'>)
dash-app-1  | Received value of type <class 'NoneType'>:
dash-app-1  |     None
dash-app-1  | 172.18.0.1 - - [01/Oct/2025 14:31:33] "POST /_dash-update-component HTTP/1.1" 500 -
dash-app-1  | 172.18.0.1 - - [01/Oct/2025 14:32:24] "POST /_dash-update-component HTTP/1.1" 200 -
dash-app-1  | [2025-10-01 14:32:24,477] ERROR in app: Exception on /_dash-update-component [POST]
dash-app-1  | Traceback (most recent call last):
dash-app-1  |   File "/usr/local/lib/python3.12/site-packages/flask/app.py", line 1473, in wsgi_app
dash-app-1  |     response = self.full_dispatch_request()
dash-app-1  |                ^^^^^^^^^^^^^^^^^^^^^^^^^^^^
dash-app-1  |   File "/usr/local/lib/python3.12/site-packages/flask/app.py", line 882, in full_dispatch_request
dash-app-1  |     rv = self.handle_user_exception(e)
dash-app-1  |          ^^^^^^^^^^^^^^^^^^^^^^^^^^^^^
dash-app-1  |   File "/usr/local/lib/python3.12/site-packages/flask/app.py", line 880, in full_dispatch_request
dash-app-1  |     rv = self.dispatch_request()
dash-app-1  |          ^^^^^^^^^^^^^^^^^^^^^^^
dash-app-1  |   File "/usr/local/lib/python3.12/site-packages/flask/app.py", line 865, in dispatch_request
dash-app-1  |     return self.ensure_sync(self.view_functions[rule.endpoint])(**view_args)  # type: ignore[no-any-return]
dash-app-1  |            ^^^^^^^^^^^^^^^^^^^^^^^^^^^^^^^^^^^^^^^^^^^^^^^^^^^^^^^^^^^^^^^^^
dash-app-1  |   File "/usr/local/lib/python3.12/site-packages/dash/dash.py", line 1414, in dispatch
dash-app-1  |     ctx.run(
dash-app-1  |   File "/usr/local/lib/python3.12/site-packages/dash/_callback.py", line 554, in add_context
dash-app-1  |     flat_output_values = flatten_grouping(output_value, output)
dash-app-1  |                          ^^^^^^^^^^^^^^^^^^^^^^^^^^^^^^^^^^^^^^
dash-app-1  |   File "/usr/local/lib/python3.12/site-packages/dash/_grouping.py", line 35, in flatten_grouping
dash-app-1  |     validate_grouping(grouping, schema)
dash-app-1  |   File "/usr/local/lib/python3.12/site-packages/dash/_grouping.py", line 210, in validate_grouping
dash-app-1  |     SchemaTypeValidationError.check(grouping, full_schema, path, (tuple, list))
dash-app-1  |   File "/usr/local/lib/python3.12/site-packages/dash/_grouping.py", line 162, in check
dash-app-1  |     raise SchemaTypeValidationError(value, full_schema, path, expected_type)
dash-app-1  | dash._grouping.SchemaTypeValidationError: Schema: [<Output `graph_container.children`>, <Output `retention_rate.disabled`>, <Output `admin.disabled`>, <Output `percentage_number.options`>, <Output `year_yearmonth.options`>, <Output `active_veryactive.options`>]
dash-app-1  | Path: ()
dash-app-1  | Expected type: (<class 'tuple'>, <class 'list'>)
dash-app-1  | Received value of type <class 'NoneType'>:
dash-app-1  |     None
dash-app-1  | 172.18.0.1 - - [01/Oct/2025 14:32:24] "POST /_dash-update-component HTTP/1.1" 500 -
       

